CRITICAL 2024-12-18 13:28:02,666 views Se forteaza logarea!
CRITICAL 2024-12-18 13:28:15,010 views Se forteaza logarea!
WARNING 2024-12-18 13:28:44,419 views Email deja confirmat pentru utilizatorul marius.
WARNING 2024-12-18 13:29:25,461 views Produsul cu id-ul furnizat nu exista!
WARNING 2024-12-18 13:29:38,896 views Utilizatorul cu id-ul furnizat nu exista!
WARNING 2024-12-18 14:22:30,913 log Not Found: /favicon.ico
WARNING 2024-12-18 14:22:30,913 basehttp "GET /favicon.ico HTTP/1.1" 404 2362
WARNING 2024-12-18 14:23:14,394 log Not Found: /favicon.ico
WARNING 2024-12-18 14:23:14,394 basehttp "GET /favicon.ico HTTP/1.1" 404 2362
WARNING 2024-12-18 15:06:36,915 log Forbidden: /aplicatie/adauga_autor/
WARNING 2024-12-18 15:06:36,916 basehttp "POST /aplicatie/adauga_autor/ HTTP/1.1" 403 377
WARNING 2024-12-18 15:08:14,031 log Forbidden: /aplicatie/adauga_autor/
WARNING 2024-12-18 15:08:14,033 basehttp "GET /aplicatie/adauga_autor/ HTTP/1.1" 403 377
WARNING 2024-12-18 15:10:54,239 log Forbidden: /aplicatie/adauga_autor/
WARNING 2024-12-18 15:10:54,239 basehttp "GET /aplicatie/adauga_autor/ HTTP/1.1" 403 366
WARNING 2024-12-18 15:15:23,218 log Forbidden: /aplicatie/adauga_autor/
WARNING 2024-12-18 15:15:23,219 basehttp "GET /aplicatie/adauga_autor/ HTTP/1.1" 403 377
WARNING 2024-12-18 15:15:26,841 log Not Found: /accounts/login/
WARNING 2024-12-18 15:15:26,842 basehttp "GET /accounts/login/?next=/aplicatie/home HTTP/1.1" 404 2395
WARNING 2024-12-19 12:39:36,604 log Not Found: /favicon.ico
WARNING 2024-12-19 12:39:36,612 basehttp "GET /favicon.ico HTTP/1.1" 404 2362
WARNING 2024-12-19 14:05:27,756 log Forbidden: /aplicatie/adauga_autor/
WARNING 2024-12-19 14:05:27,756 basehttp "GET /aplicatie/adauga_autor/ HTTP/1.1" 403 377
WARNING 2024-12-19 14:05:27,871 log Not Found: /favicon.ico
WARNING 2024-12-19 14:05:27,871 basehttp "GET /favicon.ico HTTP/1.1" 404 2362
ERROR 2024-12-19 14:20:11,347 log Internal Server Error: /aplicatie/logout
Traceback (most recent call last):
  File "C:\Users\Mihai Telu\AppData\Local\Programs\Python\Python312\Lib\site-packages\django\core\handlers\exception.py", line 55, in inner
    response = get_response(request)
               ^^^^^^^^^^^^^^^^^^^^^
  File "C:\Users\Mihai Telu\AppData\Local\Programs\Python\Python312\Lib\site-packages\django\core\handlers\base.py", line 197, in _get_response
    response = wrapped_callback(request, *callback_args, **callback_kwargs)
               ^^^^^^^^^^^^^^^^^^^^^^^^^^^^^^^^^^^^^^^^^^^^^^^^^^^^^^^^^^^^
  File "C:\Users\Mihai Telu\Django\Proiectul_meu\aplicatie\views.py", line 370, in logout2
    request.user.user_permissions.delete(permission)
    ^^^^^^^^^^^^^^^^^^^^^^^^^^^^^^^^^^^^
AttributeError: 'ManyRelatedManager' object has no attribute 'delete'
ERROR 2024-12-19 14:20:11,357 basehttp "GET /aplicatie/logout HTTP/1.1" 500 68924
WARNING 2024-12-19 14:30:30,680 log Forbidden: /aplicatie/da_permisiune/
WARNING 2024-12-19 14:30:30,680 basehttp "GET /aplicatie/da_permisiune/ HTTP/1.1" 403 14
WARNING 2025-01-04 13:22:35,820 log Not Found: /favicon.ico
WARNING 2025-01-04 13:22:35,821 basehttp "GET /favicon.ico HTTP/1.1" 404 2362
CRITICAL 2025-01-04 16:43:41,875 views Cineva vrea sa autentifice ca admin, fara sa fie!
CRITICAL 2025-01-04 16:45:27,364 views Se forteaza logarea!
CRITICAL 2025-01-04 16:45:42,559 views Se forteaza logarea!
CRITICAL 2025-01-04 16:45:58,797 views Se forteaza logarea!
ERROR 2025-01-04 17:30:50,241 log Internal Server Error: /aplicatie/sitemap.xml
Traceback (most recent call last):
  File "C:\Users\Mihai Telu\AppData\Local\Programs\Python\Python312\Lib\site-packages\django\core\handlers\exception.py", line 55, in inner
    response = get_response(request)
               ^^^^^^^^^^^^^^^^^^^^^
  File "C:\Users\Mihai Telu\AppData\Local\Programs\Python\Python312\Lib\site-packages\django\core\handlers\base.py", line 197, in _get_response
    response = wrapped_callback(request, *callback_args, **callback_kwargs)
               ^^^^^^^^^^^^^^^^^^^^^^^^^^^^^^^^^^^^^^^^^^^^^^^^^^^^^^^^^^^^
  File "C:\Users\Mihai Telu\AppData\Local\Programs\Python\Python312\Lib\site-packages\django\contrib\sitemaps\views.py", line 23, in inner
    response = func(request, *args, **kwargs)
               ^^^^^^^^^^^^^^^^^^^^^^^^^^^^^^
  File "C:\Users\Mihai Telu\AppData\Local\Programs\Python\Python312\Lib\site-packages\django\contrib\sitemaps\views.py", line 117, in sitemap
    urls.extend(site.get_urls(page=page, site=req_site, protocol=req_protocol))
                ^^^^^^^^^^^^^^^^^^^^^^^^^^^^^^^^^^^^^^^^^^^^^^^^^^^^^^^^^^^^^^
  File "C:\Users\Mihai Telu\AppData\Local\Programs\Python\Python312\Lib\site-packages\django\contrib\sitemaps\__init__.py", line 104, in get_urls
    return self._urls(page, protocol, domain)
           ^^^^^^^^^^^^^^^^^^^^^^^^^^^^^^^^^^
  File "C:\Users\Mihai Telu\AppData\Local\Programs\Python\Python312\Lib\site-packages\django\contrib\sitemaps\__init__.py", line 124, in _urls
    loc = f"{protocol}://{domain}{self._location(item)}"
                                  ^^^^^^^^^^^^^^^^^^^^
  File "C:\Users\Mihai Telu\AppData\Local\Programs\Python\Python312\Lib\site-packages\django\contrib\sitemaps\__init__.py", line 69, in _location
    return self._get("location", item)
           ^^^^^^^^^^^^^^^^^^^^^^^^^^^
  File "C:\Users\Mihai Telu\AppData\Local\Programs\Python\Python312\Lib\site-packages\django\contrib\sitemaps\__init__.py", line 39, in _get
    return attr(item)
           ^^^^^^^^^^
  File "C:\Users\Mihai Telu\AppData\Local\Programs\Python\Python312\Lib\site-packages\django\contrib\sitemaps\__init__.py", line 79, in location
    return item.get_absolute_url()
           ^^^^^^^^^^^^^^^^^^^^^^^
  File "C:\Users\Mihai Telu\Django\Proiectul_meu\aplicatie\models.py", line 37, in get_absolute_url
    return reverse('delatii_carte', kwargs={'id': self.id})
           ^^^^^^^^^^^^^^^^^^^^^^^^^^^^^^^^^^^^^^^^^^^^^^^^
  File "C:\Users\Mihai Telu\AppData\Local\Programs\Python\Python312\Lib\site-packages\django\urls\base.py", line 88, in reverse
    return resolver._reverse_with_prefix(view, prefix, *args, **kwargs)
           ^^^^^^^^^^^^^^^^^^^^^^^^^^^^^^^^^^^^^^^^^^^^^^^^^^^^^^^^^^^^
  File "C:\Users\Mihai Telu\AppData\Local\Programs\Python\Python312\Lib\site-packages\django\urls\resolvers.py", line 831, in _reverse_with_prefix
    raise NoReverseMatch(msg)
django.urls.exceptions.NoReverseMatch: Reverse for 'delatii_carte' not found. 'delatii_carte' is not a valid view function or pattern name.
ERROR 2025-01-04 17:30:50,252 basehttp "GET /aplicatie/sitemap.xml HTTP/1.1" 500 112573
ERROR 2025-01-04 18:03:06,045 log Internal Server Error: /aplicatie/sitemap.xml
Traceback (most recent call last):
  File "C:\Users\Mihai Telu\AppData\Local\Programs\Python\Python312\Lib\site-packages\django\core\handlers\exception.py", line 55, in inner
    response = get_response(request)
               ^^^^^^^^^^^^^^^^^^^^^
  File "C:\Users\Mihai Telu\AppData\Local\Programs\Python\Python312\Lib\site-packages\django\core\handlers\base.py", line 197, in _get_response
    response = wrapped_callback(request, *callback_args, **callback_kwargs)
               ^^^^^^^^^^^^^^^^^^^^^^^^^^^^^^^^^^^^^^^^^^^^^^^^^^^^^^^^^^^^
  File "C:\Users\Mihai Telu\AppData\Local\Programs\Python\Python312\Lib\site-packages\django\contrib\sitemaps\views.py", line 23, in inner
    response = func(request, *args, **kwargs)
               ^^^^^^^^^^^^^^^^^^^^^^^^^^^^^^
  File "C:\Users\Mihai Telu\AppData\Local\Programs\Python\Python312\Lib\site-packages\django\contrib\sitemaps\views.py", line 117, in sitemap
    urls.extend(site.get_urls(page=page, site=req_site, protocol=req_protocol))
                ^^^^^^^^^^^^^^^^^^^^^^^^^^^^^^^^^^^^^^^^^^^^^^^^^^^^^^^^^^^^^^
  File "C:\Users\Mihai Telu\AppData\Local\Programs\Python\Python312\Lib\site-packages\django\contrib\sitemaps\__init__.py", line 104, in get_urls
    return self._urls(page, protocol, domain)
           ^^^^^^^^^^^^^^^^^^^^^^^^^^^^^^^^^^
  File "C:\Users\Mihai Telu\AppData\Local\Programs\Python\Python312\Lib\site-packages\django\contrib\sitemaps\__init__.py", line 124, in _urls
    loc = f"{protocol}://{domain}{self._location(item)}"
                                  ^^^^^^^^^^^^^^^^^^^^
  File "C:\Users\Mihai Telu\AppData\Local\Programs\Python\Python312\Lib\site-packages\django\contrib\sitemaps\__init__.py", line 69, in _location
    return self._get("location", item)
           ^^^^^^^^^^^^^^^^^^^^^^^^^^^
  File "C:\Users\Mihai Telu\AppData\Local\Programs\Python\Python312\Lib\site-packages\django\contrib\sitemaps\__init__.py", line 39, in _get
    return attr(item)
           ^^^^^^^^^^
  File "C:\Users\Mihai Telu\AppData\Local\Programs\Python\Python312\Lib\site-packages\django\contrib\sitemaps\__init__.py", line 79, in location
    return item.get_absolute_url()
           ^^^^^^^^^^^^^^^^^^^^^^^
  File "C:\Users\Mihai Telu\Django\Proiectul_meu\aplicatie\models.py", line 37, in get_absolute_url
    return reverse('delatii_carte', kwargs={'id': self.id})
           ^^^^^^^^^^^^^^^^^^^^^^^^^^^^^^^^^^^^^^^^^^^^^^^^
  File "C:\Users\Mihai Telu\AppData\Local\Programs\Python\Python312\Lib\site-packages\django\urls\base.py", line 88, in reverse
    return resolver._reverse_with_prefix(view, prefix, *args, **kwargs)
           ^^^^^^^^^^^^^^^^^^^^^^^^^^^^^^^^^^^^^^^^^^^^^^^^^^^^^^^^^^^^
  File "C:\Users\Mihai Telu\AppData\Local\Programs\Python\Python312\Lib\site-packages\django\urls\resolvers.py", line 831, in _reverse_with_prefix
    raise NoReverseMatch(msg)
django.urls.exceptions.NoReverseMatch: Reverse for 'delatii_carte' not found. 'delatii_carte' is not a valid view function or pattern name.
ERROR 2025-01-04 18:03:06,055 basehttp "GET /aplicatie/sitemap.xml HTTP/1.1" 500 112573
ERROR 2025-01-04 18:05:25,184 log Internal Server Error: /aplicatie/detalii_carte/4
Traceback (most recent call last):
  File "C:\Users\Mihai Telu\AppData\Local\Programs\Python\Python312\Lib\site-packages\django\core\handlers\exception.py", line 55, in inner
    response = get_response(request)
               ^^^^^^^^^^^^^^^^^^^^^
  File "C:\Users\Mihai Telu\AppData\Local\Programs\Python\Python312\Lib\site-packages\django\core\handlers\base.py", line 197, in _get_response
    response = wrapped_callback(request, *callback_args, **callback_kwargs)
               ^^^^^^^^^^^^^^^^^^^^^^^^^^^^^^^^^^^^^^^^^^^^^^^^^^^^^^^^^^^^
  File "C:\Users\Mihai Telu\Django\Proiectul_meu\aplicatie\views.py", line 540, in detalii_carte
    return render(request, 'delatii_carte.html', {'carte': carte})
           ^^^^^^^^^^^^^^^^^^^^^^^^^^^^^^^^^^^^^^^^^^^^^^^^^^^^^^^
  File "C:\Users\Mihai Telu\AppData\Local\Programs\Python\Python312\Lib\site-packages\django\shortcuts.py", line 25, in render
    content = loader.render_to_string(template_name, context, request, using=using)
              ^^^^^^^^^^^^^^^^^^^^^^^^^^^^^^^^^^^^^^^^^^^^^^^^^^^^^^^^^^^^^^^^^^^^^
  File "C:\Users\Mihai Telu\AppData\Local\Programs\Python\Python312\Lib\site-packages\django\template\loader.py", line 61, in render_to_string
    template = get_template(template_name, using=using)
               ^^^^^^^^^^^^^^^^^^^^^^^^^^^^^^^^^^^^^^^^
  File "C:\Users\Mihai Telu\AppData\Local\Programs\Python\Python312\Lib\site-packages\django\template\loader.py", line 19, in get_template
    raise TemplateDoesNotExist(template_name, chain=chain)
django.template.exceptions.TemplateDoesNotExist: delatii_carte.html
ERROR 2025-01-04 18:05:25,188 basehttp "GET /aplicatie/detalii_carte/4 HTTP/1.1" 500 84720
ERROR 2025-01-04 18:06:37,585 log Internal Server Error: /aplicatie/detalii_carte/8
Traceback (most recent call last):
  File "C:\Users\Mihai Telu\AppData\Local\Programs\Python\Python312\Lib\site-packages\django\core\handlers\exception.py", line 55, in inner
    response = get_response(request)
               ^^^^^^^^^^^^^^^^^^^^^
  File "C:\Users\Mihai Telu\AppData\Local\Programs\Python\Python312\Lib\site-packages\django\core\handlers\base.py", line 197, in _get_response
    response = wrapped_callback(request, *callback_args, **callback_kwargs)
               ^^^^^^^^^^^^^^^^^^^^^^^^^^^^^^^^^^^^^^^^^^^^^^^^^^^^^^^^^^^^
  File "C:\Users\Mihai Telu\Django\Proiectul_meu\aplicatie\views.py", line 540, in detalii_carte
    return render(request, 'delatii_carte.html', {'carte': carte})
           ^^^^^^^^^^^^^^^^^^^^^^^^^^^^^^^^^^^^^^^^^^^^^^^^^^^^^^^
  File "C:\Users\Mihai Telu\AppData\Local\Programs\Python\Python312\Lib\site-packages\django\shortcuts.py", line 25, in render
    content = loader.render_to_string(template_name, context, request, using=using)
              ^^^^^^^^^^^^^^^^^^^^^^^^^^^^^^^^^^^^^^^^^^^^^^^^^^^^^^^^^^^^^^^^^^^^^
  File "C:\Users\Mihai Telu\AppData\Local\Programs\Python\Python312\Lib\site-packages\django\template\loader.py", line 61, in render_to_string
    template = get_template(template_name, using=using)
               ^^^^^^^^^^^^^^^^^^^^^^^^^^^^^^^^^^^^^^^^
  File "C:\Users\Mihai Telu\AppData\Local\Programs\Python\Python312\Lib\site-packages\django\template\loader.py", line 19, in get_template
    raise TemplateDoesNotExist(template_name, chain=chain)
django.template.exceptions.TemplateDoesNotExist: delatii_carte.html
ERROR 2025-01-04 18:06:37,590 basehttp "GET /aplicatie/detalii_carte/8 HTTP/1.1" 500 84720
ERROR 2025-01-04 18:16:26,876 log Internal Server Error: /aplicatie/paginare/
Traceback (most recent call last):
  File "C:\Users\Mihai Telu\AppData\Local\Programs\Python\Python312\Lib\site-packages\django\core\handlers\exception.py", line 55, in inner
    response = get_response(request)
               ^^^^^^^^^^^^^^^^^^^^^
  File "C:\Users\Mihai Telu\AppData\Local\Programs\Python\Python312\Lib\site-packages\django\core\handlers\base.py", line 197, in _get_response
    response = wrapped_callback(request, *callback_args, **callback_kwargs)
               ^^^^^^^^^^^^^^^^^^^^^^^^^^^^^^^^^^^^^^^^^^^^^^^^^^^^^^^^^^^^
  File "C:\Users\Mihai Telu\Django\Proiectul_meu\aplicatie\views.py", line 103, in paginare
    n= int(request.GET.get('pagina'))
       ^^^^^^^^^^^^^^^^^^^^^^^^^^^^^^
TypeError: int() argument must be a string, a bytes-like object or a real number, not 'NoneType'
ERROR 2025-01-04 18:16:26,880 basehttp "GET /aplicatie/paginare/ HTTP/1.1" 500 69277
ERROR 2025-01-04 18:17:45,220 log Internal Server Error: /aplicatie/paginare/
Traceback (most recent call last):
  File "C:\Users\Mihai Telu\AppData\Local\Programs\Python\Python312\Lib\site-packages\django\core\handlers\exception.py", line 55, in inner
    response = get_response(request)
               ^^^^^^^^^^^^^^^^^^^^^
  File "C:\Users\Mihai Telu\AppData\Local\Programs\Python\Python312\Lib\site-packages\django\core\handlers\base.py", line 197, in _get_response
    response = wrapped_callback(request, *callback_args, **callback_kwargs)
               ^^^^^^^^^^^^^^^^^^^^^^^^^^^^^^^^^^^^^^^^^^^^^^^^^^^^^^^^^^^^
  File "C:\Users\Mihai Telu\Django\Proiectul_meu\aplicatie\views.py", line 103, in paginare
    n= int(request.GET.get('pagina'))
       ^^^^^^^^^^^^^^^^^^^^^^^^^^^^^^
TypeError: int() argument must be a string, a bytes-like object or a real number, not 'NoneType'
ERROR 2025-01-04 18:17:45,223 basehttp "GET /aplicatie/paginare/ HTTP/1.1" 500 69277
WARNING 2025-01-04 18:17:56,910 log Not Found: /aplicatie/paginare/2
WARNING 2025-01-04 18:17:56,911 basehttp "GET /aplicatie/paginare/2 HTTP/1.1" 404 8858
ERROR 2025-01-04 18:18:24,981 log Internal Server Error: /aplicatie/paginare/
Traceback (most recent call last):
  File "C:\Users\Mihai Telu\AppData\Local\Programs\Python\Python312\Lib\site-packages\django\core\handlers\exception.py", line 55, in inner
    response = get_response(request)
               ^^^^^^^^^^^^^^^^^^^^^
  File "C:\Users\Mihai Telu\AppData\Local\Programs\Python\Python312\Lib\site-packages\django\core\handlers\base.py", line 197, in _get_response
    response = wrapped_callback(request, *callback_args, **callback_kwargs)
               ^^^^^^^^^^^^^^^^^^^^^^^^^^^^^^^^^^^^^^^^^^^^^^^^^^^^^^^^^^^^
  File "C:\Users\Mihai Telu\Django\Proiectul_meu\aplicatie\views.py", line 103, in paginare
    n= int(request.GET.get('pagina'))
       ^^^^^^^^^^^^^^^^^^^^^^^^^^^^^^
TypeError: int() argument must be a string, a bytes-like object or a real number, not 'NoneType'
ERROR 2025-01-04 18:18:24,985 basehttp "GET /aplicatie/paginare/ HTTP/1.1" 500 69277
ERROR 2025-01-04 18:19:20,178 log Internal Server Error: /aplicatie/paginare/
Traceback (most recent call last):
  File "C:\Users\Mihai Telu\AppData\Local\Programs\Python\Python312\Lib\site-packages\django\core\handlers\exception.py", line 55, in inner
    response = get_response(request)
               ^^^^^^^^^^^^^^^^^^^^^
  File "C:\Users\Mihai Telu\AppData\Local\Programs\Python\Python312\Lib\site-packages\django\core\handlers\base.py", line 197, in _get_response
    response = wrapped_callback(request, *callback_args, **callback_kwargs)
               ^^^^^^^^^^^^^^^^^^^^^^^^^^^^^^^^^^^^^^^^^^^^^^^^^^^^^^^^^^^^
  File "C:\Users\Mihai Telu\Django\Proiectul_meu\aplicatie\views.py", line 103, in paginare
    n= int(request.GET.get('pagina'))
       ^^^^^^^^^^^^^^^^^^^^^^^^^^^^^^
TypeError: int() argument must be a string, a bytes-like object or a real number, not 'NoneType'
ERROR 2025-01-04 18:19:20,182 basehttp "GET /aplicatie/paginare/?page=1 HTTP/1.1" 500 69628
WARNING 2025-01-05 13:01:46,939 log Not Found: /aplicatie/admin
WARNING 2025-01-05 13:01:46,941 basehttp "GET /aplicatie/admin HTTP/1.1" 404 8843
ERROR 2025-01-05 13:55:13,859 log Internal Server Error: /aplicatie/login
Traceback (most recent call last):
  File "C:\Users\Mihai Telu\AppData\Local\Programs\Python\Python312\Lib\site-packages\django\core\handlers\exception.py", line 55, in inner
    response = get_response(request)
               ^^^^^^^^^^^^^^^^^^^^^
  File "C:\Users\Mihai Telu\AppData\Local\Programs\Python\Python312\Lib\site-packages\django\core\handlers\base.py", line 197, in _get_response
    response = wrapped_callback(request, *callback_args, **callback_kwargs)
               ^^^^^^^^^^^^^^^^^^^^^^^^^^^^^^^^^^^^^^^^^^^^^^^^^^^^^^^^^^^^
  File "C:\Users\Mihai Telu\Django\Proiectul_meu\aplicatie\views.py", line 300, in login_view
    return redirect('user_login')
           ^^^^^^^^^^^^^^^^^^^^^^
  File "C:\Users\Mihai Telu\AppData\Local\Programs\Python\Python312\Lib\site-packages\django\shortcuts.py", line 49, in redirect
    return redirect_class(resolve_url(to, *args, **kwargs))
                          ^^^^^^^^^^^^^^^^^^^^^^^^^^^^^^^^
  File "C:\Users\Mihai Telu\AppData\Local\Programs\Python\Python312\Lib\site-packages\django\shortcuts.py", line 180, in resolve_url
    return reverse(to, args=args, kwargs=kwargs)
           ^^^^^^^^^^^^^^^^^^^^^^^^^^^^^^^^^^^^^
  File "C:\Users\Mihai Telu\AppData\Local\Programs\Python\Python312\Lib\site-packages\django\urls\base.py", line 88, in reverse
    return resolver._reverse_with_prefix(view, prefix, *args, **kwargs)
           ^^^^^^^^^^^^^^^^^^^^^^^^^^^^^^^^^^^^^^^^^^^^^^^^^^^^^^^^^^^^
  File "C:\Users\Mihai Telu\AppData\Local\Programs\Python\Python312\Lib\site-packages\django\urls\resolvers.py", line 831, in _reverse_with_prefix
    raise NoReverseMatch(msg)
django.urls.exceptions.NoReverseMatch: Reverse for 'user_login' not found. 'user_login' is not a valid view function or pattern name.
ERROR 2025-01-05 13:55:13,864 basehttp "POST /aplicatie/login HTTP/1.1" 500 89173
WARNING 2025-01-06 11:01:50,003 log Not Found: /aplicatie/cos_produse
WARNING 2025-01-06 11:01:50,005 basehttp "GET /aplicatie/cos_produse HTTP/1.1" 404 9136
ERROR 2025-01-06 11:02:08,533 log Internal Server Error: /aplicatie/cos_virtual/
Traceback (most recent call last):
  File "C:\Users\Mihai Telu\AppData\Local\Programs\Python\Python312\Lib\site-packages\django\db\models\sql\query.py", line 2195, in add_fields
    join_info = self.setup_joins(
                ^^^^^^^^^^^^^^^^^
  File "C:\Users\Mihai Telu\AppData\Local\Programs\Python\Python312\Lib\site-packages\django\db\models\sql\query.py", line 1863, in setup_joins
    path, final_field, targets, rest = self.names_to_path(
                                       ^^^^^^^^^^^^^^^^^^^
  File "C:\Users\Mihai Telu\AppData\Local\Programs\Python\Python312\Lib\site-packages\django\db\models\sql\query.py", line 1768, in names_to_path
    raise FieldError(
django.core.exceptions.FieldError: Cannot resolve keyword 'autor.nume' into field. Choices are: autor, autor_id, categorie, ceva, comanda, comenzi, coperta, data_publicatie, edituri, id, librarie, librarii, nr_pagini, nr_stoc, pret, recenzie, stoc, titlu, vizualizari

During handling of the above exception, another exception occurred:

Traceback (most recent call last):
  File "C:\Users\Mihai Telu\AppData\Local\Programs\Python\Python312\Lib\site-packages\django\core\handlers\exception.py", line 55, in inner
    response = get_response(request)
               ^^^^^^^^^^^^^^^^^^^^^
  File "C:\Users\Mihai Telu\AppData\Local\Programs\Python\Python312\Lib\site-packages\django\core\handlers\base.py", line 197, in _get_response
    response = wrapped_callback(request, *callback_args, **callback_kwargs)
               ^^^^^^^^^^^^^^^^^^^^^^^^^^^^^^^^^^^^^^^^^^^^^^^^^^^^^^^^^^^^
  File "C:\Users\Mihai Telu\Django\Proiectul_meu\aplicatie\views.py", line 555, in cos_virtual
    produse_in_serie = json.dumps(list(produse.values('id', 'titlu', 'autor.nume', 'pret', 'nr_stoc')), cls=DjangoJSONEncoder)
                                       ^^^^^^^^^^^^^^^^^^^^^^^^^^^^^^^^^^^^^^^^^^^^^^^^^^^^^^^^^^^^^^
  File "C:\Users\Mihai Telu\AppData\Local\Programs\Python\Python312\Lib\site-packages\django\db\models\query.py", line 1360, in values
    clone = self._values(*fields, **expressions)
            ^^^^^^^^^^^^^^^^^^^^^^^^^^^^^^^^^^^^
  File "C:\Users\Mihai Telu\AppData\Local\Programs\Python\Python312\Lib\site-packages\django\db\models\query.py", line 1355, in _values
    clone.query.set_values(fields)
  File "C:\Users\Mihai Telu\AppData\Local\Programs\Python\Python312\Lib\site-packages\django\db\models\sql\query.py", line 2500, in set_values
    self.add_fields(field_names, True)
  File "C:\Users\Mihai Telu\AppData\Local\Programs\Python\Python312\Lib\site-packages\django\db\models\sql\query.py", line 2223, in add_fields
    raise FieldError(
django.core.exceptions.FieldError: Cannot resolve keyword 'autor.nume' into field. Choices are: autor, autor_id, categorie, ceva, comanda, comenzi, coperta, data_publicatie, edituri, id, librarie, librarii, nr_pagini, nr_stoc, pret, recenzie, stoc, titlu, vizualizari
ERROR 2025-01-06 11:02:08,543 basehttp "GET /aplicatie/cos_virtual/ HTTP/1.1" 500 110520
ERROR 2025-01-06 11:02:14,346 log Internal Server Error: /aplicatie/cos_virtual/
Traceback (most recent call last):
  File "C:\Users\Mihai Telu\AppData\Local\Programs\Python\Python312\Lib\site-packages\django\db\models\sql\query.py", line 2195, in add_fields
    join_info = self.setup_joins(
                ^^^^^^^^^^^^^^^^^
  File "C:\Users\Mihai Telu\AppData\Local\Programs\Python\Python312\Lib\site-packages\django\db\models\sql\query.py", line 1863, in setup_joins
    path, final_field, targets, rest = self.names_to_path(
                                       ^^^^^^^^^^^^^^^^^^^
  File "C:\Users\Mihai Telu\AppData\Local\Programs\Python\Python312\Lib\site-packages\django\db\models\sql\query.py", line 1768, in names_to_path
    raise FieldError(
django.core.exceptions.FieldError: Cannot resolve keyword 'autor.nume' into field. Choices are: autor, autor_id, categorie, ceva, comanda, comenzi, coperta, data_publicatie, edituri, id, librarie, librarii, nr_pagini, nr_stoc, pret, recenzie, stoc, titlu, vizualizari

During handling of the above exception, another exception occurred:

Traceback (most recent call last):
  File "C:\Users\Mihai Telu\AppData\Local\Programs\Python\Python312\Lib\site-packages\django\core\handlers\exception.py", line 55, in inner
    response = get_response(request)
               ^^^^^^^^^^^^^^^^^^^^^
  File "C:\Users\Mihai Telu\AppData\Local\Programs\Python\Python312\Lib\site-packages\django\core\handlers\base.py", line 197, in _get_response
    response = wrapped_callback(request, *callback_args, **callback_kwargs)
               ^^^^^^^^^^^^^^^^^^^^^^^^^^^^^^^^^^^^^^^^^^^^^^^^^^^^^^^^^^^^
  File "C:\Users\Mihai Telu\Django\Proiectul_meu\aplicatie\views.py", line 555, in cos_virtual
    produse_in_serie = json.dumps(list(produse.values('id', 'titlu', 'autor.nume', 'pret', 'nr_stoc')), cls=DjangoJSONEncoder)
                                       ^^^^^^^^^^^^^^^^^^^^^^^^^^^^^^^^^^^^^^^^^^^^^^^^^^^^^^^^^^^^^^
  File "C:\Users\Mihai Telu\AppData\Local\Programs\Python\Python312\Lib\site-packages\django\db\models\query.py", line 1360, in values
    clone = self._values(*fields, **expressions)
            ^^^^^^^^^^^^^^^^^^^^^^^^^^^^^^^^^^^^
  File "C:\Users\Mihai Telu\AppData\Local\Programs\Python\Python312\Lib\site-packages\django\db\models\query.py", line 1355, in _values
    clone.query.set_values(fields)
  File "C:\Users\Mihai Telu\AppData\Local\Programs\Python\Python312\Lib\site-packages\django\db\models\sql\query.py", line 2500, in set_values
    self.add_fields(field_names, True)
  File "C:\Users\Mihai Telu\AppData\Local\Programs\Python\Python312\Lib\site-packages\django\db\models\sql\query.py", line 2223, in add_fields
    raise FieldError(
django.core.exceptions.FieldError: Cannot resolve keyword 'autor.nume' into field. Choices are: autor, autor_id, categorie, ceva, comanda, comenzi, coperta, data_publicatie, edituri, id, librarie, librarii, nr_pagini, nr_stoc, pret, recenzie, stoc, titlu, vizualizari
ERROR 2025-01-06 11:02:14,354 basehttp "GET /aplicatie/cos_virtual/ HTTP/1.1" 500 110520
ERROR 2025-01-06 11:02:57,973 log Internal Server Error: /aplicatie/cos_virtual/
Traceback (most recent call last):
  File "C:\Users\Mihai Telu\AppData\Local\Programs\Python\Python312\Lib\site-packages\django\db\models\sql\query.py", line 2195, in add_fields
    join_info = self.setup_joins(
                ^^^^^^^^^^^^^^^^^
  File "C:\Users\Mihai Telu\AppData\Local\Programs\Python\Python312\Lib\site-packages\django\db\models\sql\query.py", line 1863, in setup_joins
    path, final_field, targets, rest = self.names_to_path(
                                       ^^^^^^^^^^^^^^^^^^^
  File "C:\Users\Mihai Telu\AppData\Local\Programs\Python\Python312\Lib\site-packages\django\db\models\sql\query.py", line 1768, in names_to_path
    raise FieldError(
django.core.exceptions.FieldError: Cannot resolve keyword 'autor.nume' into field. Choices are: autor, autor_id, categorie, ceva, comanda, comenzi, coperta, data_publicatie, edituri, id, librarie, librarii, nr_pagini, nr_stoc, pret, recenzie, stoc, titlu, vizualizari

During handling of the above exception, another exception occurred:

Traceback (most recent call last):
  File "C:\Users\Mihai Telu\AppData\Local\Programs\Python\Python312\Lib\site-packages\django\core\handlers\exception.py", line 55, in inner
    response = get_response(request)
               ^^^^^^^^^^^^^^^^^^^^^
  File "C:\Users\Mihai Telu\AppData\Local\Programs\Python\Python312\Lib\site-packages\django\core\handlers\base.py", line 197, in _get_response
    response = wrapped_callback(request, *callback_args, **callback_kwargs)
               ^^^^^^^^^^^^^^^^^^^^^^^^^^^^^^^^^^^^^^^^^^^^^^^^^^^^^^^^^^^^
  File "C:\Users\Mihai Telu\Django\Proiectul_meu\aplicatie\views.py", line 555, in cos_virtual
    produse_in_serie = json.dumps(list(produse.values('id', 'titlu', 'autor.nume', 'pret', 'nr_stoc')), cls=DjangoJSONEncoder)
                                       ^^^^^^^^^^^^^^^^^^^^^^^^^^^^^^^^^^^^^^^^^^^^^^^^^^^^^^^^^^^^^^
  File "C:\Users\Mihai Telu\AppData\Local\Programs\Python\Python312\Lib\site-packages\django\db\models\query.py", line 1360, in values
    clone = self._values(*fields, **expressions)
            ^^^^^^^^^^^^^^^^^^^^^^^^^^^^^^^^^^^^
  File "C:\Users\Mihai Telu\AppData\Local\Programs\Python\Python312\Lib\site-packages\django\db\models\query.py", line 1355, in _values
    clone.query.set_values(fields)
  File "C:\Users\Mihai Telu\AppData\Local\Programs\Python\Python312\Lib\site-packages\django\db\models\sql\query.py", line 2500, in set_values
    self.add_fields(field_names, True)
  File "C:\Users\Mihai Telu\AppData\Local\Programs\Python\Python312\Lib\site-packages\django\db\models\sql\query.py", line 2223, in add_fields
    raise FieldError(
django.core.exceptions.FieldError: Cannot resolve keyword 'autor.nume' into field. Choices are: autor, autor_id, categorie, ceva, comanda, comenzi, coperta, data_publicatie, edituri, id, librarie, librarii, nr_pagini, nr_stoc, pret, recenzie, stoc, titlu, vizualizari
ERROR 2025-01-06 11:02:57,983 basehttp "GET /aplicatie/cos_virtual/ HTTP/1.1" 500 110657
ERROR 2025-01-06 11:07:03,704 log Internal Server Error: /aplicatie/cos_virtual/
Traceback (most recent call last):
  File "C:\Users\Mihai Telu\AppData\Local\Programs\Python\Python312\Lib\site-packages\django\db\models\sql\query.py", line 2195, in add_fields
    join_info = self.setup_joins(
                ^^^^^^^^^^^^^^^^^
  File "C:\Users\Mihai Telu\AppData\Local\Programs\Python\Python312\Lib\site-packages\django\db\models\sql\query.py", line 1863, in setup_joins
    path, final_field, targets, rest = self.names_to_path(
                                       ^^^^^^^^^^^^^^^^^^^
  File "C:\Users\Mihai Telu\AppData\Local\Programs\Python\Python312\Lib\site-packages\django\db\models\sql\query.py", line 1768, in names_to_path
    raise FieldError(
django.core.exceptions.FieldError: Cannot resolve keyword 'autor_nume' into field. Choices are: autor, autor_id, categorie, ceva, comanda, comenzi, coperta, data_publicatie, edituri, id, librarie, librarii, nr_pagini, nr_stoc, pret, recenzie, stoc, titlu, vizualizari

During handling of the above exception, another exception occurred:

Traceback (most recent call last):
  File "C:\Users\Mihai Telu\AppData\Local\Programs\Python\Python312\Lib\site-packages\django\core\handlers\exception.py", line 55, in inner
    response = get_response(request)
               ^^^^^^^^^^^^^^^^^^^^^
  File "C:\Users\Mihai Telu\AppData\Local\Programs\Python\Python312\Lib\site-packages\django\core\handlers\base.py", line 197, in _get_response
    response = wrapped_callback(request, *callback_args, **callback_kwargs)
               ^^^^^^^^^^^^^^^^^^^^^^^^^^^^^^^^^^^^^^^^^^^^^^^^^^^^^^^^^^^^
  File "C:\Users\Mihai Telu\Django\Proiectul_meu\aplicatie\views.py", line 555, in cos_virtual
    produse_in_serie = json.dumps(list(produse.values('id', 'titlu', 'autor_nume', 'pret', 'nr_stoc')), cls=DjangoJSONEncoder)
                                       ^^^^^^^^^^^^^^^^^^^^^^^^^^^^^^^^^^^^^^^^^^^^^^^^^^^^^^^^^^^^^^
  File "C:\Users\Mihai Telu\AppData\Local\Programs\Python\Python312\Lib\site-packages\django\db\models\query.py", line 1360, in values
    clone = self._values(*fields, **expressions)
            ^^^^^^^^^^^^^^^^^^^^^^^^^^^^^^^^^^^^
  File "C:\Users\Mihai Telu\AppData\Local\Programs\Python\Python312\Lib\site-packages\django\db\models\query.py", line 1355, in _values
    clone.query.set_values(fields)
  File "C:\Users\Mihai Telu\AppData\Local\Programs\Python\Python312\Lib\site-packages\django\db\models\sql\query.py", line 2500, in set_values
    self.add_fields(field_names, True)
  File "C:\Users\Mihai Telu\AppData\Local\Programs\Python\Python312\Lib\site-packages\django\db\models\sql\query.py", line 2223, in add_fields
    raise FieldError(
django.core.exceptions.FieldError: Cannot resolve keyword 'autor_nume' into field. Choices are: autor, autor_id, categorie, ceva, comanda, comenzi, coperta, data_publicatie, edituri, id, librarie, librarii, nr_pagini, nr_stoc, pret, recenzie, stoc, titlu, vizualizari
ERROR 2025-01-06 11:07:03,711 basehttp "GET /aplicatie/cos_virtual/ HTTP/1.1" 500 110657
ERROR 2025-01-06 19:05:01,693 log Internal Server Error: /aplicatie/cumpara_cos/
Traceback (most recent call last):
  File "C:\Users\Mihai Telu\AppData\Local\Programs\Python\Python312\Lib\site-packages\django\core\handlers\exception.py", line 55, in inner
    response = get_response(request)
               ^^^^^^^^^^^^^^^^^^^^^
  File "C:\Users\Mihai Telu\AppData\Local\Programs\Python\Python312\Lib\site-packages\django\core\handlers\base.py", line 197, in _get_response
    response = wrapped_callback(request, *callback_args, **callback_kwargs)
               ^^^^^^^^^^^^^^^^^^^^^^^^^^^^^^^^^^^^^^^^^^^^^^^^^^^^^^^^^^^^
  File "C:\Users\Mihai Telu\AppData\Local\Programs\Python\Python312\Lib\site-packages\django\contrib\auth\decorators.py", line 60, in _view_wrapper
    return view_func(request, *args, **kwargs)
           ^^^^^^^^^^^^^^^^^^^^^^^^^^^^^^^^^^^
  File "C:\Users\Mihai Telu\Django\Proiectul_meu\aplicatie\views.py", line 579, in cumpara_cos
    id, titlu, cantitate, pret, stoc = item.split("/")
    ^^^^^^^^^^^^^^^^^^^^^^^^^^^^^^^^
ValueError: not enough values to unpack (expected 5, got 1)
ERROR 2025-01-06 19:05:01,699 basehttp "POST /aplicatie/cumpara_cos/ HTTP/1.1" 500 75139
ERROR 2025-01-06 19:08:40,475 log Internal Server Error: /aplicatie/cumpara_cos/
Traceback (most recent call last):
  File "C:\Users\Mihai Telu\AppData\Local\Programs\Python\Python312\Lib\site-packages\django\core\handlers\exception.py", line 55, in inner
    response = get_response(request)
               ^^^^^^^^^^^^^^^^^^^^^
  File "C:\Users\Mihai Telu\AppData\Local\Programs\Python\Python312\Lib\site-packages\django\core\handlers\base.py", line 197, in _get_response
    response = wrapped_callback(request, *callback_args, **callback_kwargs)
               ^^^^^^^^^^^^^^^^^^^^^^^^^^^^^^^^^^^^^^^^^^^^^^^^^^^^^^^^^^^^
  File "C:\Users\Mihai Telu\AppData\Local\Programs\Python\Python312\Lib\site-packages\django\contrib\auth\decorators.py", line 60, in _view_wrapper
    return view_func(request, *args, **kwargs)
           ^^^^^^^^^^^^^^^^^^^^^^^^^^^^^^^^^^^
  File "C:\Users\Mihai Telu\Django\Proiectul_meu\aplicatie\views.py", line 579, in cumpara_cos
    id, titlu, cantitate, pret, stoc = item.split("/")
    ^^^^^^^^^^^^^^^^^^^^^^^^^^^^^^^^
ValueError: not enough values to unpack (expected 5, got 1)
ERROR 2025-01-06 19:08:40,479 basehttp "POST /aplicatie/cumpara_cos/ HTTP/1.1" 500 75139
ERROR 2025-01-06 19:10:47,469 log Internal Server Error: /aplicatie/cumpara_cos/
Traceback (most recent call last):
  File "C:\Users\Mihai Telu\AppData\Local\Programs\Python\Python312\Lib\site-packages\django\core\handlers\exception.py", line 55, in inner
    response = get_response(request)
               ^^^^^^^^^^^^^^^^^^^^^
  File "C:\Users\Mihai Telu\AppData\Local\Programs\Python\Python312\Lib\site-packages\django\core\handlers\base.py", line 197, in _get_response
    response = wrapped_callback(request, *callback_args, **callback_kwargs)
               ^^^^^^^^^^^^^^^^^^^^^^^^^^^^^^^^^^^^^^^^^^^^^^^^^^^^^^^^^^^^
  File "C:\Users\Mihai Telu\AppData\Local\Programs\Python\Python312\Lib\site-packages\django\contrib\auth\decorators.py", line 60, in _view_wrapper
    return view_func(request, *args, **kwargs)
           ^^^^^^^^^^^^^^^^^^^^^^^^^^^^^^^^^^^
  File "C:\Users\Mihai Telu\Django\Proiectul_meu\aplicatie\views.py", line 579, in cumpara_cos
    id, titlu, cantitate, pret, stoc = item.split("/")
    ^^^^^^^^^^^^^^^^^^^^^^^^^^^^^^^^
ValueError: not enough values to unpack (expected 5, got 1)
ERROR 2025-01-06 19:10:47,474 basehttp "POST /aplicatie/cumpara_cos/ HTTP/1.1" 500 75139
ERROR 2025-01-06 19:10:58,786 log Internal Server Error: /aplicatie/cumpara_cos/
Traceback (most recent call last):
  File "C:\Users\Mihai Telu\AppData\Local\Programs\Python\Python312\Lib\site-packages\django\core\handlers\exception.py", line 55, in inner
    response = get_response(request)
               ^^^^^^^^^^^^^^^^^^^^^
  File "C:\Users\Mihai Telu\AppData\Local\Programs\Python\Python312\Lib\site-packages\django\core\handlers\base.py", line 197, in _get_response
    response = wrapped_callback(request, *callback_args, **callback_kwargs)
               ^^^^^^^^^^^^^^^^^^^^^^^^^^^^^^^^^^^^^^^^^^^^^^^^^^^^^^^^^^^^
  File "C:\Users\Mihai Telu\AppData\Local\Programs\Python\Python312\Lib\site-packages\django\contrib\auth\decorators.py", line 60, in _view_wrapper
    return view_func(request, *args, **kwargs)
           ^^^^^^^^^^^^^^^^^^^^^^^^^^^^^^^^^^^
  File "C:\Users\Mihai Telu\Django\Proiectul_meu\aplicatie\views.py", line 579, in cumpara_cos
    id, titlu, cantitate, pret, stoc = item.split("/")
    ^^^^^^^^^^^^^^^^^^^^^^^^^^^^^^^^
ValueError: not enough values to unpack (expected 5, got 1)
ERROR 2025-01-06 19:10:58,791 basehttp "POST /aplicatie/cumpara_cos/ HTTP/1.1" 500 75139
ERROR 2025-01-06 19:27:38,490 log Internal Server Error: /aplicatie/cumpara_cos/
Traceback (most recent call last):
  File "C:\Users\Mihai Telu\AppData\Local\Programs\Python\Python312\Lib\site-packages\django\core\handlers\exception.py", line 55, in inner
    response = get_response(request)
               ^^^^^^^^^^^^^^^^^^^^^
  File "C:\Users\Mihai Telu\AppData\Local\Programs\Python\Python312\Lib\site-packages\django\core\handlers\base.py", line 197, in _get_response
    response = wrapped_callback(request, *callback_args, **callback_kwargs)
               ^^^^^^^^^^^^^^^^^^^^^^^^^^^^^^^^^^^^^^^^^^^^^^^^^^^^^^^^^^^^
  File "C:\Users\Mihai Telu\AppData\Local\Programs\Python\Python312\Lib\site-packages\django\contrib\auth\decorators.py", line 60, in _view_wrapper
    return view_func(request, *args, **kwargs)
           ^^^^^^^^^^^^^^^^^^^^^^^^^^^^^^^^^^^
  File "C:\Users\Mihai Telu\Django\Proiectul_meu\aplicatie\views.py", line 579, in cumpara_cos
    id = item.get('id')
         ^^^^^^^^
AttributeError: 'str' object has no attribute 'get'
ERROR 2025-01-06 19:27:38,495 basehttp "POST /aplicatie/cumpara_cos/ HTTP/1.1" 500 75043
ERROR 2025-01-06 19:30:18,679 log Internal Server Error: /aplicatie/cumpara_cos/
Traceback (most recent call last):
  File "C:\Users\Mihai Telu\AppData\Local\Programs\Python\Python312\Lib\site-packages\django\core\handlers\exception.py", line 55, in inner
    response = get_response(request)
               ^^^^^^^^^^^^^^^^^^^^^
  File "C:\Users\Mihai Telu\AppData\Local\Programs\Python\Python312\Lib\site-packages\django\core\handlers\base.py", line 197, in _get_response
    response = wrapped_callback(request, *callback_args, **callback_kwargs)
               ^^^^^^^^^^^^^^^^^^^^^^^^^^^^^^^^^^^^^^^^^^^^^^^^^^^^^^^^^^^^
  File "C:\Users\Mihai Telu\AppData\Local\Programs\Python\Python312\Lib\site-packages\django\contrib\auth\decorators.py", line 60, in _view_wrapper
    return view_func(request, *args, **kwargs)
           ^^^^^^^^^^^^^^^^^^^^^^^^^^^^^^^^^^^
  File "C:\Users\Mihai Telu\Django\Proiectul_meu\aplicatie\views.py", line 578, in cumpara_cos
    print (item+'----------------------------------------')
           ^^^^
UnboundLocalError: cannot access local variable 'item' where it is not associated with a value
ERROR 2025-01-06 19:30:18,685 basehttp "POST /aplicatie/cumpara_cos/ HTTP/1.1" 500 75080
ERROR 2025-01-06 19:30:46,554 log Internal Server Error: /aplicatie/cumpara_cos/
Traceback (most recent call last):
  File "C:\Users\Mihai Telu\AppData\Local\Programs\Python\Python312\Lib\site-packages\django\core\handlers\exception.py", line 55, in inner
    response = get_response(request)
               ^^^^^^^^^^^^^^^^^^^^^
  File "C:\Users\Mihai Telu\AppData\Local\Programs\Python\Python312\Lib\site-packages\django\core\handlers\base.py", line 197, in _get_response
    response = wrapped_callback(request, *callback_args, **callback_kwargs)
               ^^^^^^^^^^^^^^^^^^^^^^^^^^^^^^^^^^^^^^^^^^^^^^^^^^^^^^^^^^^^
  File "C:\Users\Mihai Telu\AppData\Local\Programs\Python\Python312\Lib\site-packages\django\contrib\auth\decorators.py", line 60, in _view_wrapper
    return view_func(request, *args, **kwargs)
           ^^^^^^^^^^^^^^^^^^^^^^^^^^^^^^^^^^^
  File "C:\Users\Mihai Telu\Django\Proiectul_meu\aplicatie\views.py", line 581, in cumpara_cos
    id = item.get('id')
         ^^^^^^^^
AttributeError: 'str' object has no attribute 'get'
ERROR 2025-01-06 19:30:46,558 basehttp "POST /aplicatie/cumpara_cos/ HTTP/1.1" 500 75112
ERROR 2025-01-06 19:32:09,679 log Internal Server Error: /aplicatie/cumpara_cos/
Traceback (most recent call last):
  File "C:\Users\Mihai Telu\AppData\Local\Programs\Python\Python312\Lib\site-packages\django\core\handlers\exception.py", line 55, in inner
    response = get_response(request)
               ^^^^^^^^^^^^^^^^^^^^^
  File "C:\Users\Mihai Telu\AppData\Local\Programs\Python\Python312\Lib\site-packages\django\core\handlers\base.py", line 197, in _get_response
    response = wrapped_callback(request, *callback_args, **callback_kwargs)
               ^^^^^^^^^^^^^^^^^^^^^^^^^^^^^^^^^^^^^^^^^^^^^^^^^^^^^^^^^^^^
  File "C:\Users\Mihai Telu\AppData\Local\Programs\Python\Python312\Lib\site-packages\django\contrib\auth\decorators.py", line 60, in _view_wrapper
    return view_func(request, *args, **kwargs)
           ^^^^^^^^^^^^^^^^^^^^^^^^^^^^^^^^^^^
  File "C:\Users\Mihai Telu\Django\Proiectul_meu\aplicatie\views.py", line 581, in cumpara_cos
    id = item.get('id')
         ^^^^^^^^
AttributeError: 'str' object has no attribute 'get'
ERROR 2025-01-06 19:32:09,685 basehttp "POST /aplicatie/cumpara_cos/ HTTP/1.1" 500 75059
ERROR 2025-01-06 19:33:51,749 log Internal Server Error: /aplicatie/cumpara_cos/
Traceback (most recent call last):
  File "C:\Users\Mihai Telu\AppData\Local\Programs\Python\Python312\Lib\site-packages\django\core\handlers\exception.py", line 55, in inner
    response = get_response(request)
               ^^^^^^^^^^^^^^^^^^^^^
  File "C:\Users\Mihai Telu\AppData\Local\Programs\Python\Python312\Lib\site-packages\django\core\handlers\base.py", line 197, in _get_response
    response = wrapped_callback(request, *callback_args, **callback_kwargs)
               ^^^^^^^^^^^^^^^^^^^^^^^^^^^^^^^^^^^^^^^^^^^^^^^^^^^^^^^^^^^^
  File "C:\Users\Mihai Telu\AppData\Local\Programs\Python\Python312\Lib\site-packages\django\contrib\auth\decorators.py", line 60, in _view_wrapper
    return view_func(request, *args, **kwargs)
           ^^^^^^^^^^^^^^^^^^^^^^^^^^^^^^^^^^^
  File "C:\Users\Mihai Telu\Django\Proiectul_meu\aplicatie\views.py", line 581, in cumpara_cos
    id = item.get('id')
         ^^^^^^^^
AttributeError: 'str' object has no attribute 'get'
ERROR 2025-01-06 19:33:51,754 basehttp "POST /aplicatie/cumpara_cos/ HTTP/1.1" 500 75077
ERROR 2025-01-06 19:39:26,453 log Internal Server Error: /aplicatie/cumpara_cos/
Traceback (most recent call last):
  File "C:\Users\Mihai Telu\AppData\Local\Programs\Python\Python312\Lib\site-packages\django\core\handlers\exception.py", line 55, in inner
    response = get_response(request)
               ^^^^^^^^^^^^^^^^^^^^^
  File "C:\Users\Mihai Telu\AppData\Local\Programs\Python\Python312\Lib\site-packages\django\core\handlers\base.py", line 197, in _get_response
    response = wrapped_callback(request, *callback_args, **callback_kwargs)
               ^^^^^^^^^^^^^^^^^^^^^^^^^^^^^^^^^^^^^^^^^^^^^^^^^^^^^^^^^^^^
  File "C:\Users\Mihai Telu\AppData\Local\Programs\Python\Python312\Lib\site-packages\django\contrib\auth\decorators.py", line 60, in _view_wrapper
    return view_func(request, *args, **kwargs)
           ^^^^^^^^^^^^^^^^^^^^^^^^^^^^^^^^^^^
  File "C:\Users\Mihai Telu\Django\Proiectul_meu\aplicatie\views.py", line 581, in cumpara_cos
    id = item.get('id')
         ^^^^^^^^
AttributeError: 'str' object has no attribute 'get'
ERROR 2025-01-06 19:39:26,457 basehttp "POST /aplicatie/cumpara_cos/ HTTP/1.1" 500 75508
ERROR 2025-01-06 22:43:02,054 log Internal Server Error: /aplicatie/cumpara_cos/
Traceback (most recent call last):
  File "C:\Users\Mihai Telu\AppData\Local\Programs\Python\Python312\Lib\site-packages\django\core\handlers\exception.py", line 55, in inner
    response = get_response(request)
               ^^^^^^^^^^^^^^^^^^^^^
  File "C:\Users\Mihai Telu\AppData\Local\Programs\Python\Python312\Lib\site-packages\django\core\handlers\base.py", line 197, in _get_response
    response = wrapped_callback(request, *callback_args, **callback_kwargs)
               ^^^^^^^^^^^^^^^^^^^^^^^^^^^^^^^^^^^^^^^^^^^^^^^^^^^^^^^^^^^^
  File "C:\Users\Mihai Telu\AppData\Local\Programs\Python\Python312\Lib\site-packages\django\contrib\auth\decorators.py", line 60, in _view_wrapper
    return view_func(request, *args, **kwargs)
           ^^^^^^^^^^^^^^^^^^^^^^^^^^^^^^^^^^^
  File "C:\Users\Mihai Telu\Django\Proiectul_meu\aplicatie\views.py", line 581, in cumpara_cos
    id = item.get('id')
         ^^^^^^^^
AttributeError: 'str' object has no attribute 'get'
ERROR 2025-01-06 22:43:02,060 basehttp "POST /aplicatie/cumpara_cos/ HTTP/1.1" 500 75508
ERROR 2025-01-06 22:43:39,416 log Internal Server Error: /aplicatie/cumpara_cos/
Traceback (most recent call last):
  File "C:\Users\Mihai Telu\AppData\Local\Programs\Python\Python312\Lib\site-packages\django\core\handlers\exception.py", line 55, in inner
    response = get_response(request)
               ^^^^^^^^^^^^^^^^^^^^^
  File "C:\Users\Mihai Telu\AppData\Local\Programs\Python\Python312\Lib\site-packages\django\core\handlers\base.py", line 197, in _get_response
    response = wrapped_callback(request, *callback_args, **callback_kwargs)
               ^^^^^^^^^^^^^^^^^^^^^^^^^^^^^^^^^^^^^^^^^^^^^^^^^^^^^^^^^^^^
  File "C:\Users\Mihai Telu\AppData\Local\Programs\Python\Python312\Lib\site-packages\django\contrib\auth\decorators.py", line 60, in _view_wrapper
    return view_func(request, *args, **kwargs)
           ^^^^^^^^^^^^^^^^^^^^^^^^^^^^^^^^^^^
  File "C:\Users\Mihai Telu\Django\Proiectul_meu\aplicatie\views.py", line 581, in cumpara_cos
    id = item.get('id')
         ^^^^^^^^
AttributeError: 'str' object has no attribute 'get'
ERROR 2025-01-06 22:43:39,421 basehttp "POST /aplicatie/cumpara_cos/ HTTP/1.1" 500 75508
ERROR 2025-01-06 22:45:09,981 log Internal Server Error: /aplicatie/cumpara_cos/
Traceback (most recent call last):
  File "C:\Users\Mihai Telu\AppData\Local\Programs\Python\Python312\Lib\site-packages\django\core\handlers\exception.py", line 55, in inner
    response = get_response(request)
               ^^^^^^^^^^^^^^^^^^^^^
  File "C:\Users\Mihai Telu\AppData\Local\Programs\Python\Python312\Lib\site-packages\django\core\handlers\base.py", line 197, in _get_response
    response = wrapped_callback(request, *callback_args, **callback_kwargs)
               ^^^^^^^^^^^^^^^^^^^^^^^^^^^^^^^^^^^^^^^^^^^^^^^^^^^^^^^^^^^^
  File "C:\Users\Mihai Telu\AppData\Local\Programs\Python\Python312\Lib\site-packages\django\contrib\auth\decorators.py", line 60, in _view_wrapper
    return view_func(request, *args, **kwargs)
           ^^^^^^^^^^^^^^^^^^^^^^^^^^^^^^^^^^^
  File "C:\Users\Mihai Telu\Django\Proiectul_meu\aplicatie\views.py", line 581, in cumpara_cos
    id = item.get('id')
         ^^^^^^^^
AttributeError: 'str' object has no attribute 'get'
ERROR 2025-01-06 22:45:09,987 basehttp "POST /aplicatie/cumpara_cos/ HTTP/1.1" 500 75508
ERROR 2025-01-06 22:52:58,754 log Internal Server Error: /aplicatie/cumpara_cos/
Traceback (most recent call last):
  File "C:\Users\Mihai Telu\AppData\Local\Programs\Python\Python312\Lib\site-packages\django\core\handlers\exception.py", line 55, in inner
    response = get_response(request)
               ^^^^^^^^^^^^^^^^^^^^^
  File "C:\Users\Mihai Telu\AppData\Local\Programs\Python\Python312\Lib\site-packages\django\core\handlers\base.py", line 197, in _get_response
    response = wrapped_callback(request, *callback_args, **callback_kwargs)
               ^^^^^^^^^^^^^^^^^^^^^^^^^^^^^^^^^^^^^^^^^^^^^^^^^^^^^^^^^^^^
  File "C:\Users\Mihai Telu\AppData\Local\Programs\Python\Python312\Lib\site-packages\django\contrib\auth\decorators.py", line 60, in _view_wrapper
    return view_func(request, *args, **kwargs)
           ^^^^^^^^^^^^^^^^^^^^^^^^^^^^^^^^^^^
  File "C:\Users\Mihai Telu\Django\Proiectul_meu\aplicatie\views.py", line 581, in cumpara_cos
    id = item.get('id')
         ^^^^^^^^
AttributeError: 'str' object has no attribute 'get'
ERROR 2025-01-06 22:52:58,758 basehttp "POST /aplicatie/cumpara_cos/ HTTP/1.1" 500 75163
ERROR 2025-01-06 22:58:50,965 log Internal Server Error: /aplicatie/cumpara_cos/
Traceback (most recent call last):
  File "C:\Users\Mihai Telu\AppData\Local\Programs\Python\Python312\Lib\site-packages\django\core\handlers\exception.py", line 55, in inner
    response = get_response(request)
               ^^^^^^^^^^^^^^^^^^^^^
  File "C:\Users\Mihai Telu\AppData\Local\Programs\Python\Python312\Lib\site-packages\django\core\handlers\base.py", line 197, in _get_response
    response = wrapped_callback(request, *callback_args, **callback_kwargs)
               ^^^^^^^^^^^^^^^^^^^^^^^^^^^^^^^^^^^^^^^^^^^^^^^^^^^^^^^^^^^^
  File "C:\Users\Mihai Telu\AppData\Local\Programs\Python\Python312\Lib\site-packages\django\contrib\auth\decorators.py", line 60, in _view_wrapper
    return view_func(request, *args, **kwargs)
           ^^^^^^^^^^^^^^^^^^^^^^^^^^^^^^^^^^^
  File "C:\Users\Mihai Telu\Django\Proiectul_meu\aplicatie\views.py", line 580, in cumpara_cos
    print (item[id])
                ^^
UnboundLocalError: cannot access local variable 'id' where it is not associated with a value
ERROR 2025-01-06 22:58:50,969 basehttp "POST /aplicatie/cumpara_cos/ HTTP/1.1" 500 75245
ERROR 2025-01-06 23:02:33,188 log Internal Server Error: /aplicatie/cumpara_cos/
Traceback (most recent call last):
  File "C:\Users\Mihai Telu\AppData\Local\Programs\Python\Python312\Lib\site-packages\django\core\handlers\exception.py", line 55, in inner
    response = get_response(request)
               ^^^^^^^^^^^^^^^^^^^^^
  File "C:\Users\Mihai Telu\AppData\Local\Programs\Python\Python312\Lib\site-packages\django\core\handlers\base.py", line 197, in _get_response
    response = wrapped_callback(request, *callback_args, **callback_kwargs)
               ^^^^^^^^^^^^^^^^^^^^^^^^^^^^^^^^^^^^^^^^^^^^^^^^^^^^^^^^^^^^
  File "C:\Users\Mihai Telu\AppData\Local\Programs\Python\Python312\Lib\site-packages\django\contrib\auth\decorators.py", line 60, in _view_wrapper
    return view_func(request, *args, **kwargs)
           ^^^^^^^^^^^^^^^^^^^^^^^^^^^^^^^^^^^
  File "C:\Users\Mihai Telu\Django\Proiectul_meu\aplicatie\views.py", line 580, in cumpara_cos
    print (item.get('id'))
           ^^^^^^^^
AttributeError: 'str' object has no attribute 'get'
ERROR 2025-01-06 23:02:33,195 basehttp "POST /aplicatie/cumpara_cos/ HTTP/1.1" 500 75191
ERROR 2025-01-06 23:05:50,205 log Internal Server Error: /aplicatie/cumpara_cos/
Traceback (most recent call last):
  File "C:\Users\Mihai Telu\AppData\Local\Programs\Python\Python312\Lib\site-packages\django\core\handlers\exception.py", line 55, in inner
    response = get_response(request)
               ^^^^^^^^^^^^^^^^^^^^^
  File "C:\Users\Mihai Telu\AppData\Local\Programs\Python\Python312\Lib\site-packages\django\core\handlers\base.py", line 197, in _get_response
    response = wrapped_callback(request, *callback_args, **callback_kwargs)
               ^^^^^^^^^^^^^^^^^^^^^^^^^^^^^^^^^^^^^^^^^^^^^^^^^^^^^^^^^^^^
  File "C:\Users\Mihai Telu\AppData\Local\Programs\Python\Python312\Lib\site-packages\django\contrib\auth\decorators.py", line 60, in _view_wrapper
    return view_func(request, *args, **kwargs)
           ^^^^^^^^^^^^^^^^^^^^^^^^^^^^^^^^^^^
  File "C:\Users\Mihai Telu\Django\Proiectul_meu\aplicatie\views.py", line 596, in cumpara_cos
    factura_path = genereaza_factura(utilizator, carti_comandate, total_cantitate, total_pret)
                   ^^^^^^^^^^^^^^^^^^^^^^^^^^^^^^^^^^^^^^^^^^^^^^^^^^^^^^^^^^^^^^^^^^^^^^^^^^^
  File "C:\Users\Mihai Telu\Django\Proiectul_meu\aplicatie\views.py", line 629, in genereaza_factura
    lk = f"http://localhost:8000/aplicatie/detalii_carte/{comanda.carte.id}"
                                                          ^^^^^^^^^^^^^
AttributeError: 'tuple' object has no attribute 'carte'
ERROR 2025-01-06 23:05:50,211 basehttp "POST /aplicatie/cumpara_cos/ HTTP/1.1" 500 83071
ERROR 2025-01-06 23:13:54,170 log Internal Server Error: /aplicatie/cumpara_cos/
Traceback (most recent call last):
  File "C:\Users\Mihai Telu\AppData\Local\Programs\Python\Python312\Lib\site-packages\django\core\handlers\exception.py", line 55, in inner
    response = get_response(request)
               ^^^^^^^^^^^^^^^^^^^^^
  File "C:\Users\Mihai Telu\AppData\Local\Programs\Python\Python312\Lib\site-packages\django\core\handlers\base.py", line 197, in _get_response
    response = wrapped_callback(request, *callback_args, **callback_kwargs)
               ^^^^^^^^^^^^^^^^^^^^^^^^^^^^^^^^^^^^^^^^^^^^^^^^^^^^^^^^^^^^
  File "C:\Users\Mihai Telu\AppData\Local\Programs\Python\Python312\Lib\site-packages\django\contrib\auth\decorators.py", line 60, in _view_wrapper
    return view_func(request, *args, **kwargs)
           ^^^^^^^^^^^^^^^^^^^^^^^^^^^^^^^^^^^
  File "C:\Users\Mihai Telu\Django\Proiectul_meu\aplicatie\views.py", line 594, in cumpara_cos
    factura_path = genereaza_factura(utilizator, carti_comandate, total_cantitate, total_pret)
                   ^^^^^^^^^^^^^^^^^^^^^^^^^^^^^^^^^^^^^^^^^^^^^^^^^^^^^^^^^^^^^^^^^^^^^^^^^^^
  File "C:\Users\Mihai Telu\Django\Proiectul_meu\aplicatie\views.py", line 627, in genereaza_factura
    lk = f"http://localhost:8000/aplicatie/detalii_carte/{comanda.id}"
                                                          ^^^^^^^^^^
AttributeError: 'tuple' object has no attribute 'id'
ERROR 2025-01-06 23:13:54,175 basehttp "POST /aplicatie/cumpara_cos/ HTTP/1.1" 500 82886
ERROR 2025-01-06 23:14:34,767 log Internal Server Error: /aplicatie/cumpara_cos/
Traceback (most recent call last):
  File "C:\Users\Mihai Telu\AppData\Local\Programs\Python\Python312\Lib\site-packages\django\core\handlers\exception.py", line 55, in inner
    response = get_response(request)
               ^^^^^^^^^^^^^^^^^^^^^
  File "C:\Users\Mihai Telu\AppData\Local\Programs\Python\Python312\Lib\site-packages\django\core\handlers\base.py", line 197, in _get_response
    response = wrapped_callback(request, *callback_args, **callback_kwargs)
               ^^^^^^^^^^^^^^^^^^^^^^^^^^^^^^^^^^^^^^^^^^^^^^^^^^^^^^^^^^^^
  File "C:\Users\Mihai Telu\AppData\Local\Programs\Python\Python312\Lib\site-packages\django\contrib\auth\decorators.py", line 60, in _view_wrapper
    return view_func(request, *args, **kwargs)
           ^^^^^^^^^^^^^^^^^^^^^^^^^^^^^^^^^^^
  File "C:\Users\Mihai Telu\Django\Proiectul_meu\aplicatie\views.py", line 594, in cumpara_cos
    factura_path = genereaza_factura(utilizator, carti_comandate, total_cantitate, total_pret)
                   ^^^^^^^^^^^^^^^^^^^^^^^^^^^^^^^^^^^^^^^^^^^^^^^^^^^^^^^^^^^^^^^^^^^^^^^^^^^
  File "C:\Users\Mihai Telu\Django\Proiectul_meu\aplicatie\views.py", line 627, in genereaza_factura
    lk = f"http://localhost:8000/aplicatie/detalii_carte/{comanda(0)}"
                                                          ^^^^^^^^^^
TypeError: 'tuple' object is not callable
ERROR 2025-01-06 23:14:34,772 basehttp "POST /aplicatie/cumpara_cos/ HTTP/1.1" 500 82792
ERROR 2025-01-06 23:18:00,107 log Internal Server Error: /aplicatie/cumpara_cos/
Traceback (most recent call last):
  File "C:\Users\Mihai Telu\AppData\Local\Programs\Python\Python312\Lib\site-packages\django\core\handlers\exception.py", line 55, in inner
    response = get_response(request)
               ^^^^^^^^^^^^^^^^^^^^^
  File "C:\Users\Mihai Telu\AppData\Local\Programs\Python\Python312\Lib\site-packages\django\core\handlers\base.py", line 197, in _get_response
    response = wrapped_callback(request, *callback_args, **callback_kwargs)
               ^^^^^^^^^^^^^^^^^^^^^^^^^^^^^^^^^^^^^^^^^^^^^^^^^^^^^^^^^^^^
  File "C:\Users\Mihai Telu\AppData\Local\Programs\Python\Python312\Lib\site-packages\django\contrib\auth\decorators.py", line 60, in _view_wrapper
    return view_func(request, *args, **kwargs)
           ^^^^^^^^^^^^^^^^^^^^^^^^^^^^^^^^^^^
  File "C:\Users\Mihai Telu\Django\Proiectul_meu\aplicatie\views.py", line 594, in cumpara_cos
    factura_path = genereaza_factura(utilizator, carti_comandate, total_cantitate, total_pret)
                   ^^^^^^^^^^^^^^^^^^^^^^^^^^^^^^^^^^^^^^^^^^^^^^^^^^^^^^^^^^^^^^^^^^^^^^^^^^^
  File "C:\Users\Mihai Telu\Django\Proiectul_meu\aplicatie\views.py", line 628, in genereaza_factura
    c.drawString(100, y, f"Produs: {comanda.titlu}, Cantitate: {comanda.cantitate}, Pret: {comanda.pret} RON/bucata, Link-produs: {lk}")
                                    ^^^^^^^^^^^^^
AttributeError: 'tuple' object has no attribute 'titlu'
ERROR 2025-01-06 23:18:00,113 basehttp "POST /aplicatie/cumpara_cos/ HTTP/1.1" 500 82967
WARNING 2025-01-07 00:06:07,701 log Not Found: /accounts/login/
WARNING 2025-01-07 00:06:07,703 basehttp "GET /accounts/login/?next=/aplicatie/cumpara_cos/ HTTP/1.1" 404 2403
WARNING 2025-01-07 00:06:19,763 log Not Found: /accounts/login/
WARNING 2025-01-07 00:06:19,764 basehttp "GET /accounts/login/?next=/aplicatie/home HTTP/1.1" 404 2395
WARNING 2025-01-07 00:06:25,100 log Not Found: /accounts/login
WARNING 2025-01-07 00:06:25,101 basehttp "GET /accounts/login HTTP/1.1" 404 2371
ERROR 2025-01-07 13:27:39,329 log Internal Server Error: /aplicatie/meniu/
Traceback (most recent call last):
  File "C:\Users\Mihai Telu\AppData\Local\Programs\Python\Python312\Lib\site-packages\django\template\base.py", line 510, in parse
    compile_func = self.tags[command]
                   ~~~~~~~~~^^^^^^^^^
KeyError: 'static'

During handling of the above exception, another exception occurred:

Traceback (most recent call last):
  File "C:\Users\Mihai Telu\AppData\Local\Programs\Python\Python312\Lib\site-packages\django\core\handlers\exception.py", line 55, in inner
    response = get_response(request)
               ^^^^^^^^^^^^^^^^^^^^^
  File "C:\Users\Mihai Telu\AppData\Local\Programs\Python\Python312\Lib\site-packages\django\core\handlers\base.py", line 197, in _get_response
    response = wrapped_callback(request, *callback_args, **callback_kwargs)
               ^^^^^^^^^^^^^^^^^^^^^^^^^^^^^^^^^^^^^^^^^^^^^^^^^^^^^^^^^^^^
  File "C:\Users\Mihai Telu\Django\Proiectul_meu\aplicatie\views.py", line 643, in meniu
    return render(request, 'meniu.html')
           ^^^^^^^^^^^^^^^^^^^^^^^^^^^^^
  File "C:\Users\Mihai Telu\AppData\Local\Programs\Python\Python312\Lib\site-packages\django\shortcuts.py", line 25, in render
    content = loader.render_to_string(template_name, context, request, using=using)
              ^^^^^^^^^^^^^^^^^^^^^^^^^^^^^^^^^^^^^^^^^^^^^^^^^^^^^^^^^^^^^^^^^^^^^
  File "C:\Users\Mihai Telu\AppData\Local\Programs\Python\Python312\Lib\site-packages\django\template\loader.py", line 61, in render_to_string
    template = get_template(template_name, using=using)
               ^^^^^^^^^^^^^^^^^^^^^^^^^^^^^^^^^^^^^^^^
  File "C:\Users\Mihai Telu\AppData\Local\Programs\Python\Python312\Lib\site-packages\django\template\loader.py", line 15, in get_template
    return engine.get_template(template_name)
           ^^^^^^^^^^^^^^^^^^^^^^^^^^^^^^^^^^
  File "C:\Users\Mihai Telu\AppData\Local\Programs\Python\Python312\Lib\site-packages\django\template\backends\django.py", line 79, in get_template
    return Template(self.engine.get_template(template_name), self)
                    ^^^^^^^^^^^^^^^^^^^^^^^^^^^^^^^^^^^^^^^
  File "C:\Users\Mihai Telu\AppData\Local\Programs\Python\Python312\Lib\site-packages\django\template\engine.py", line 177, in get_template
    template, origin = self.find_template(template_name)
                       ^^^^^^^^^^^^^^^^^^^^^^^^^^^^^^^^^
  File "C:\Users\Mihai Telu\AppData\Local\Programs\Python\Python312\Lib\site-packages\django\template\engine.py", line 159, in find_template
    template = loader.get_template(name, skip=skip)
               ^^^^^^^^^^^^^^^^^^^^^^^^^^^^^^^^^^^^
  File "C:\Users\Mihai Telu\AppData\Local\Programs\Python\Python312\Lib\site-packages\django\template\loaders\cached.py", line 57, in get_template
    template = super().get_template(template_name, skip)
               ^^^^^^^^^^^^^^^^^^^^^^^^^^^^^^^^^^^^^^^^^
  File "C:\Users\Mihai Telu\AppData\Local\Programs\Python\Python312\Lib\site-packages\django\template\loaders\base.py", line 28, in get_template
    return Template(
           ^^^^^^^^^
  File "C:\Users\Mihai Telu\AppData\Local\Programs\Python\Python312\Lib\site-packages\django\template\base.py", line 154, in __init__
    self.nodelist = self.compile_nodelist()
                    ^^^^^^^^^^^^^^^^^^^^^^^
  File "C:\Users\Mihai Telu\AppData\Local\Programs\Python\Python312\Lib\site-packages\django\template\base.py", line 196, in compile_nodelist
    nodelist = parser.parse()
               ^^^^^^^^^^^^^^
  File "C:\Users\Mihai Telu\AppData\Local\Programs\Python\Python312\Lib\site-packages\django\template\base.py", line 512, in parse
    self.invalid_block_tag(token, command, parse_until)
  File "C:\Users\Mihai Telu\AppData\Local\Programs\Python\Python312\Lib\site-packages\django\template\base.py", line 573, in invalid_block_tag
    raise self.error(
django.template.exceptions.TemplateSyntaxError: Invalid block tag on line 7: 'static'. Did you forget to register or load this tag?
ERROR 2025-01-07 13:27:39,348 basehttp "GET /aplicatie/meniu/ HTTP/1.1" 500 157092
ERROR 2025-01-07 13:28:12,825 log Internal Server Error: /aplicatie/meniu/
Traceback (most recent call last):
  File "C:\Users\Mihai Telu\AppData\Local\Programs\Python\Python312\Lib\site-packages\django\template\smartif.py", line 180, in translate_token
    op = OPERATORS[token]
         ~~~~~~~~~^^^^^^^
KeyError: "user.has_perm('app_name.add_vizualizare')"

During handling of the above exception, another exception occurred:

Traceback (most recent call last):
  File "C:\Users\Mihai Telu\AppData\Local\Programs\Python\Python312\Lib\site-packages\django\core\handlers\exception.py", line 55, in inner
    response = get_response(request)
               ^^^^^^^^^^^^^^^^^^^^^
  File "C:\Users\Mihai Telu\AppData\Local\Programs\Python\Python312\Lib\site-packages\django\core\handlers\base.py", line 197, in _get_response
    response = wrapped_callback(request, *callback_args, **callback_kwargs)
               ^^^^^^^^^^^^^^^^^^^^^^^^^^^^^^^^^^^^^^^^^^^^^^^^^^^^^^^^^^^^
  File "C:\Users\Mihai Telu\Django\Proiectul_meu\aplicatie\views.py", line 643, in meniu
    return render(request, 'meniu.html')
           ^^^^^^^^^^^^^^^^^^^^^^^^^^^^^
  File "C:\Users\Mihai Telu\AppData\Local\Programs\Python\Python312\Lib\site-packages\django\shortcuts.py", line 25, in render
    content = loader.render_to_string(template_name, context, request, using=using)
              ^^^^^^^^^^^^^^^^^^^^^^^^^^^^^^^^^^^^^^^^^^^^^^^^^^^^^^^^^^^^^^^^^^^^^
  File "C:\Users\Mihai Telu\AppData\Local\Programs\Python\Python312\Lib\site-packages\django\template\loader.py", line 61, in render_to_string
    template = get_template(template_name, using=using)
               ^^^^^^^^^^^^^^^^^^^^^^^^^^^^^^^^^^^^^^^^
  File "C:\Users\Mihai Telu\AppData\Local\Programs\Python\Python312\Lib\site-packages\django\template\loader.py", line 15, in get_template
    return engine.get_template(template_name)
           ^^^^^^^^^^^^^^^^^^^^^^^^^^^^^^^^^^
  File "C:\Users\Mihai Telu\AppData\Local\Programs\Python\Python312\Lib\site-packages\django\template\backends\django.py", line 79, in get_template
    return Template(self.engine.get_template(template_name), self)
                    ^^^^^^^^^^^^^^^^^^^^^^^^^^^^^^^^^^^^^^^
  File "C:\Users\Mihai Telu\AppData\Local\Programs\Python\Python312\Lib\site-packages\django\template\engine.py", line 177, in get_template
    template, origin = self.find_template(template_name)
                       ^^^^^^^^^^^^^^^^^^^^^^^^^^^^^^^^^
  File "C:\Users\Mihai Telu\AppData\Local\Programs\Python\Python312\Lib\site-packages\django\template\engine.py", line 159, in find_template
    template = loader.get_template(name, skip=skip)
               ^^^^^^^^^^^^^^^^^^^^^^^^^^^^^^^^^^^^
  File "C:\Users\Mihai Telu\AppData\Local\Programs\Python\Python312\Lib\site-packages\django\template\loaders\cached.py", line 57, in get_template
    template = super().get_template(template_name, skip)
               ^^^^^^^^^^^^^^^^^^^^^^^^^^^^^^^^^^^^^^^^^
  File "C:\Users\Mihai Telu\AppData\Local\Programs\Python\Python312\Lib\site-packages\django\template\loaders\base.py", line 28, in get_template
    return Template(
           ^^^^^^^^^
  File "C:\Users\Mihai Telu\AppData\Local\Programs\Python\Python312\Lib\site-packages\django\template\base.py", line 154, in __init__
    self.nodelist = self.compile_nodelist()
                    ^^^^^^^^^^^^^^^^^^^^^^^
  File "C:\Users\Mihai Telu\AppData\Local\Programs\Python\Python312\Lib\site-packages\django\template\base.py", line 196, in compile_nodelist
    nodelist = parser.parse()
               ^^^^^^^^^^^^^^
  File "C:\Users\Mihai Telu\AppData\Local\Programs\Python\Python312\Lib\site-packages\django\template\base.py", line 518, in parse
    raise self.error(token, e)
  File "C:\Users\Mihai Telu\AppData\Local\Programs\Python\Python312\Lib\site-packages\django\template\base.py", line 516, in parse
    compiled_result = compile_func(self, token)
                      ^^^^^^^^^^^^^^^^^^^^^^^^^
  File "C:\Users\Mihai Telu\AppData\Local\Programs\Python\Python312\Lib\site-packages\django\template\defaulttags.py", line 961, in do_if
    condition = TemplateIfParser(parser, bits).parse()
                ^^^^^^^^^^^^^^^^^^^^^^^^^^^^^^
  File "C:\Users\Mihai Telu\AppData\Local\Programs\Python\Python312\Lib\site-packages\django\template\defaulttags.py", line 894, in __init__
    super().__init__(*args, **kwargs)
  File "C:\Users\Mihai Telu\AppData\Local\Programs\Python\Python312\Lib\site-packages\django\template\smartif.py", line 171, in __init__
    mapped_tokens.append(self.translate_token(token))
                         ^^^^^^^^^^^^^^^^^^^^^^^^^^^
  File "C:\Users\Mihai Telu\AppData\Local\Programs\Python\Python312\Lib\site-packages\django\template\smartif.py", line 182, in translate_token
    return self.create_var(token)
           ^^^^^^^^^^^^^^^^^^^^^^
  File "C:\Users\Mihai Telu\AppData\Local\Programs\Python\Python312\Lib\site-packages\django\template\defaulttags.py", line 897, in create_var
    return TemplateLiteral(self.template_parser.compile_filter(value), value)
                           ^^^^^^^^^^^^^^^^^^^^^^^^^^^^^^^^^^^^^^^^^^
  File "C:\Users\Mihai Telu\AppData\Local\Programs\Python\Python312\Lib\site-packages\django\template\base.py", line 605, in compile_filter
    return FilterExpression(token, self)
           ^^^^^^^^^^^^^^^^^^^^^^^^^^^^^
  File "C:\Users\Mihai Telu\AppData\Local\Programs\Python\Python312\Lib\site-packages\django\template\base.py", line 706, in __init__
    raise TemplateSyntaxError(
django.template.exceptions.TemplateSyntaxError: Could not parse the remainder: '('app_name.add_vizualizare')' from 'user.has_perm('app_name.add_vizualizare')'
ERROR 2025-01-07 13:28:12,841 basehttp "GET /aplicatie/meniu/ HTTP/1.1" 500 185348
ERROR 2025-01-07 14:24:05,993 log Internal Server Error: /aplicatie/meniu/
Traceback (most recent call last):
  File "C:\Users\Mihai Telu\AppData\Local\Programs\Python\Python312\Lib\site-packages\django\template\smartif.py", line 180, in translate_token
    op = OPERATORS[token]
         ~~~~~~~~~^^^^^^^
KeyError: "user.has_perm('aplicatie.view_autor')"

During handling of the above exception, another exception occurred:

Traceback (most recent call last):
  File "C:\Users\Mihai Telu\AppData\Local\Programs\Python\Python312\Lib\site-packages\django\core\handlers\exception.py", line 55, in inner
    response = get_response(request)
               ^^^^^^^^^^^^^^^^^^^^^
  File "C:\Users\Mihai Telu\AppData\Local\Programs\Python\Python312\Lib\site-packages\django\core\handlers\base.py", line 197, in _get_response
    response = wrapped_callback(request, *callback_args, **callback_kwargs)
               ^^^^^^^^^^^^^^^^^^^^^^^^^^^^^^^^^^^^^^^^^^^^^^^^^^^^^^^^^^^^
  File "C:\Users\Mihai Telu\Django\Proiectul_meu\aplicatie\views.py", line 643, in meniu
    return render(request, 'meniu.html')
           ^^^^^^^^^^^^^^^^^^^^^^^^^^^^^
  File "C:\Users\Mihai Telu\AppData\Local\Programs\Python\Python312\Lib\site-packages\django\shortcuts.py", line 25, in render
    content = loader.render_to_string(template_name, context, request, using=using)
              ^^^^^^^^^^^^^^^^^^^^^^^^^^^^^^^^^^^^^^^^^^^^^^^^^^^^^^^^^^^^^^^^^^^^^
  File "C:\Users\Mihai Telu\AppData\Local\Programs\Python\Python312\Lib\site-packages\django\template\loader.py", line 61, in render_to_string
    template = get_template(template_name, using=using)
               ^^^^^^^^^^^^^^^^^^^^^^^^^^^^^^^^^^^^^^^^
  File "C:\Users\Mihai Telu\AppData\Local\Programs\Python\Python312\Lib\site-packages\django\template\loader.py", line 15, in get_template
    return engine.get_template(template_name)
           ^^^^^^^^^^^^^^^^^^^^^^^^^^^^^^^^^^
  File "C:\Users\Mihai Telu\AppData\Local\Programs\Python\Python312\Lib\site-packages\django\template\backends\django.py", line 79, in get_template
    return Template(self.engine.get_template(template_name), self)
                    ^^^^^^^^^^^^^^^^^^^^^^^^^^^^^^^^^^^^^^^
  File "C:\Users\Mihai Telu\AppData\Local\Programs\Python\Python312\Lib\site-packages\django\template\engine.py", line 177, in get_template
    template, origin = self.find_template(template_name)
                       ^^^^^^^^^^^^^^^^^^^^^^^^^^^^^^^^^
  File "C:\Users\Mihai Telu\AppData\Local\Programs\Python\Python312\Lib\site-packages\django\template\engine.py", line 159, in find_template
    template = loader.get_template(name, skip=skip)
               ^^^^^^^^^^^^^^^^^^^^^^^^^^^^^^^^^^^^
  File "C:\Users\Mihai Telu\AppData\Local\Programs\Python\Python312\Lib\site-packages\django\template\loaders\cached.py", line 57, in get_template
    template = super().get_template(template_name, skip)
               ^^^^^^^^^^^^^^^^^^^^^^^^^^^^^^^^^^^^^^^^^
  File "C:\Users\Mihai Telu\AppData\Local\Programs\Python\Python312\Lib\site-packages\django\template\loaders\base.py", line 28, in get_template
    return Template(
           ^^^^^^^^^
  File "C:\Users\Mihai Telu\AppData\Local\Programs\Python\Python312\Lib\site-packages\django\template\base.py", line 154, in __init__
    self.nodelist = self.compile_nodelist()
                    ^^^^^^^^^^^^^^^^^^^^^^^
  File "C:\Users\Mihai Telu\AppData\Local\Programs\Python\Python312\Lib\site-packages\django\template\base.py", line 196, in compile_nodelist
    nodelist = parser.parse()
               ^^^^^^^^^^^^^^
  File "C:\Users\Mihai Telu\AppData\Local\Programs\Python\Python312\Lib\site-packages\django\template\base.py", line 518, in parse
    raise self.error(token, e)
  File "C:\Users\Mihai Telu\AppData\Local\Programs\Python\Python312\Lib\site-packages\django\template\base.py", line 516, in parse
    compiled_result = compile_func(self, token)
                      ^^^^^^^^^^^^^^^^^^^^^^^^^
  File "C:\Users\Mihai Telu\AppData\Local\Programs\Python\Python312\Lib\site-packages\django\template\defaulttags.py", line 961, in do_if
    condition = TemplateIfParser(parser, bits).parse()
                ^^^^^^^^^^^^^^^^^^^^^^^^^^^^^^
  File "C:\Users\Mihai Telu\AppData\Local\Programs\Python\Python312\Lib\site-packages\django\template\defaulttags.py", line 894, in __init__
    super().__init__(*args, **kwargs)
  File "C:\Users\Mihai Telu\AppData\Local\Programs\Python\Python312\Lib\site-packages\django\template\smartif.py", line 171, in __init__
    mapped_tokens.append(self.translate_token(token))
                         ^^^^^^^^^^^^^^^^^^^^^^^^^^^
  File "C:\Users\Mihai Telu\AppData\Local\Programs\Python\Python312\Lib\site-packages\django\template\smartif.py", line 182, in translate_token
    return self.create_var(token)
           ^^^^^^^^^^^^^^^^^^^^^^
  File "C:\Users\Mihai Telu\AppData\Local\Programs\Python\Python312\Lib\site-packages\django\template\defaulttags.py", line 897, in create_var
    return TemplateLiteral(self.template_parser.compile_filter(value), value)
                           ^^^^^^^^^^^^^^^^^^^^^^^^^^^^^^^^^^^^^^^^^^
  File "C:\Users\Mihai Telu\AppData\Local\Programs\Python\Python312\Lib\site-packages\django\template\base.py", line 605, in compile_filter
    return FilterExpression(token, self)
           ^^^^^^^^^^^^^^^^^^^^^^^^^^^^^
  File "C:\Users\Mihai Telu\AppData\Local\Programs\Python\Python312\Lib\site-packages\django\template\base.py", line 706, in __init__
    raise TemplateSyntaxError(
django.template.exceptions.TemplateSyntaxError: Could not parse the remainder: '('aplicatie.view_autor')' from 'user.has_perm('aplicatie.view_autor')'
ERROR 2025-01-07 14:24:06,009 basehttp "GET /aplicatie/meniu/ HTTP/1.1" 500 178737
ERROR 2025-01-07 14:25:45,484 log Internal Server Error: /aplicatie/meniu/
Traceback (most recent call last):
  File "C:\Users\Mihai Telu\AppData\Local\Programs\Python\Python312\Lib\site-packages\django\template\smartif.py", line 180, in translate_token
    op = OPERATORS[token]
         ~~~~~~~~~^^^^^^^
KeyError: "user|has_perm('aplicatie.view_autor')"

During handling of the above exception, another exception occurred:

Traceback (most recent call last):
  File "C:\Users\Mihai Telu\AppData\Local\Programs\Python\Python312\Lib\site-packages\django\core\handlers\exception.py", line 55, in inner
    response = get_response(request)
               ^^^^^^^^^^^^^^^^^^^^^
  File "C:\Users\Mihai Telu\AppData\Local\Programs\Python\Python312\Lib\site-packages\django\core\handlers\base.py", line 197, in _get_response
    response = wrapped_callback(request, *callback_args, **callback_kwargs)
               ^^^^^^^^^^^^^^^^^^^^^^^^^^^^^^^^^^^^^^^^^^^^^^^^^^^^^^^^^^^^
  File "C:\Users\Mihai Telu\Django\Proiectul_meu\aplicatie\views.py", line 643, in meniu
    return render(request, 'meniu.html')
           ^^^^^^^^^^^^^^^^^^^^^^^^^^^^^
  File "C:\Users\Mihai Telu\AppData\Local\Programs\Python\Python312\Lib\site-packages\django\shortcuts.py", line 25, in render
    content = loader.render_to_string(template_name, context, request, using=using)
              ^^^^^^^^^^^^^^^^^^^^^^^^^^^^^^^^^^^^^^^^^^^^^^^^^^^^^^^^^^^^^^^^^^^^^
  File "C:\Users\Mihai Telu\AppData\Local\Programs\Python\Python312\Lib\site-packages\django\template\loader.py", line 61, in render_to_string
    template = get_template(template_name, using=using)
               ^^^^^^^^^^^^^^^^^^^^^^^^^^^^^^^^^^^^^^^^
  File "C:\Users\Mihai Telu\AppData\Local\Programs\Python\Python312\Lib\site-packages\django\template\loader.py", line 15, in get_template
    return engine.get_template(template_name)
           ^^^^^^^^^^^^^^^^^^^^^^^^^^^^^^^^^^
  File "C:\Users\Mihai Telu\AppData\Local\Programs\Python\Python312\Lib\site-packages\django\template\backends\django.py", line 79, in get_template
    return Template(self.engine.get_template(template_name), self)
                    ^^^^^^^^^^^^^^^^^^^^^^^^^^^^^^^^^^^^^^^
  File "C:\Users\Mihai Telu\AppData\Local\Programs\Python\Python312\Lib\site-packages\django\template\engine.py", line 177, in get_template
    template, origin = self.find_template(template_name)
                       ^^^^^^^^^^^^^^^^^^^^^^^^^^^^^^^^^
  File "C:\Users\Mihai Telu\AppData\Local\Programs\Python\Python312\Lib\site-packages\django\template\engine.py", line 159, in find_template
    template = loader.get_template(name, skip=skip)
               ^^^^^^^^^^^^^^^^^^^^^^^^^^^^^^^^^^^^
  File "C:\Users\Mihai Telu\AppData\Local\Programs\Python\Python312\Lib\site-packages\django\template\loaders\cached.py", line 57, in get_template
    template = super().get_template(template_name, skip)
               ^^^^^^^^^^^^^^^^^^^^^^^^^^^^^^^^^^^^^^^^^
  File "C:\Users\Mihai Telu\AppData\Local\Programs\Python\Python312\Lib\site-packages\django\template\loaders\base.py", line 28, in get_template
    return Template(
           ^^^^^^^^^
  File "C:\Users\Mihai Telu\AppData\Local\Programs\Python\Python312\Lib\site-packages\django\template\base.py", line 154, in __init__
    self.nodelist = self.compile_nodelist()
                    ^^^^^^^^^^^^^^^^^^^^^^^
  File "C:\Users\Mihai Telu\AppData\Local\Programs\Python\Python312\Lib\site-packages\django\template\base.py", line 196, in compile_nodelist
    nodelist = parser.parse()
               ^^^^^^^^^^^^^^
  File "C:\Users\Mihai Telu\AppData\Local\Programs\Python\Python312\Lib\site-packages\django\template\base.py", line 518, in parse
    raise self.error(token, e)
  File "C:\Users\Mihai Telu\AppData\Local\Programs\Python\Python312\Lib\site-packages\django\template\base.py", line 516, in parse
    compiled_result = compile_func(self, token)
                      ^^^^^^^^^^^^^^^^^^^^^^^^^
  File "C:\Users\Mihai Telu\AppData\Local\Programs\Python\Python312\Lib\site-packages\django\template\defaulttags.py", line 961, in do_if
    condition = TemplateIfParser(parser, bits).parse()
                ^^^^^^^^^^^^^^^^^^^^^^^^^^^^^^
  File "C:\Users\Mihai Telu\AppData\Local\Programs\Python\Python312\Lib\site-packages\django\template\defaulttags.py", line 894, in __init__
    super().__init__(*args, **kwargs)
  File "C:\Users\Mihai Telu\AppData\Local\Programs\Python\Python312\Lib\site-packages\django\template\smartif.py", line 171, in __init__
    mapped_tokens.append(self.translate_token(token))
                         ^^^^^^^^^^^^^^^^^^^^^^^^^^^
  File "C:\Users\Mihai Telu\AppData\Local\Programs\Python\Python312\Lib\site-packages\django\template\smartif.py", line 182, in translate_token
    return self.create_var(token)
           ^^^^^^^^^^^^^^^^^^^^^^
  File "C:\Users\Mihai Telu\AppData\Local\Programs\Python\Python312\Lib\site-packages\django\template\defaulttags.py", line 897, in create_var
    return TemplateLiteral(self.template_parser.compile_filter(value), value)
                           ^^^^^^^^^^^^^^^^^^^^^^^^^^^^^^^^^^^^^^^^^^
  File "C:\Users\Mihai Telu\AppData\Local\Programs\Python\Python312\Lib\site-packages\django\template\base.py", line 605, in compile_filter
    return FilterExpression(token, self)
           ^^^^^^^^^^^^^^^^^^^^^^^^^^^^^
  File "C:\Users\Mihai Telu\AppData\Local\Programs\Python\Python312\Lib\site-packages\django\template\base.py", line 701, in __init__
    filter_func = parser.find_filter(filter_name)
                  ^^^^^^^^^^^^^^^^^^^^^^^^^^^^^^^
  File "C:\Users\Mihai Telu\AppData\Local\Programs\Python\Python312\Lib\site-packages\django\template\base.py", line 611, in find_filter
    raise TemplateSyntaxError("Invalid filter: '%s'" % filter_name)
django.template.exceptions.TemplateSyntaxError: Invalid filter: 'has_perm'
ERROR 2025-01-07 14:25:45,500 basehttp "GET /aplicatie/meniu/ HTTP/1.1" 500 183296
ERROR 2025-01-07 14:28:37,691 log Internal Server Error: /aplicatie/meniu/
Traceback (most recent call last):
  File "C:\Users\Mihai Telu\AppData\Local\Programs\Python\Python312\Lib\site-packages\django\template\base.py", line 510, in parse
    compile_func = self.tags[command]
                   ~~~~~~~~~^^^^^^^^^
KeyError: 'endif'

During handling of the above exception, another exception occurred:

Traceback (most recent call last):
  File "C:\Users\Mihai Telu\AppData\Local\Programs\Python\Python312\Lib\site-packages\django\core\handlers\exception.py", line 55, in inner
    response = get_response(request)
               ^^^^^^^^^^^^^^^^^^^^^
  File "C:\Users\Mihai Telu\AppData\Local\Programs\Python\Python312\Lib\site-packages\django\core\handlers\base.py", line 197, in _get_response
    response = wrapped_callback(request, *callback_args, **callback_kwargs)
               ^^^^^^^^^^^^^^^^^^^^^^^^^^^^^^^^^^^^^^^^^^^^^^^^^^^^^^^^^^^^
  File "C:\Users\Mihai Telu\Django\Proiectul_meu\aplicatie\views.py", line 644, in meniu
    return render(request, 'meniu.html',{'ok':ok})
           ^^^^^^^^^^^^^^^^^^^^^^^^^^^^^^^^^^^^^^^
  File "C:\Users\Mihai Telu\AppData\Local\Programs\Python\Python312\Lib\site-packages\django\shortcuts.py", line 25, in render
    content = loader.render_to_string(template_name, context, request, using=using)
              ^^^^^^^^^^^^^^^^^^^^^^^^^^^^^^^^^^^^^^^^^^^^^^^^^^^^^^^^^^^^^^^^^^^^^
  File "C:\Users\Mihai Telu\AppData\Local\Programs\Python\Python312\Lib\site-packages\django\template\loader.py", line 61, in render_to_string
    template = get_template(template_name, using=using)
               ^^^^^^^^^^^^^^^^^^^^^^^^^^^^^^^^^^^^^^^^
  File "C:\Users\Mihai Telu\AppData\Local\Programs\Python\Python312\Lib\site-packages\django\template\loader.py", line 15, in get_template
    return engine.get_template(template_name)
           ^^^^^^^^^^^^^^^^^^^^^^^^^^^^^^^^^^
  File "C:\Users\Mihai Telu\AppData\Local\Programs\Python\Python312\Lib\site-packages\django\template\backends\django.py", line 79, in get_template
    return Template(self.engine.get_template(template_name), self)
                    ^^^^^^^^^^^^^^^^^^^^^^^^^^^^^^^^^^^^^^^
  File "C:\Users\Mihai Telu\AppData\Local\Programs\Python\Python312\Lib\site-packages\django\template\engine.py", line 177, in get_template
    template, origin = self.find_template(template_name)
                       ^^^^^^^^^^^^^^^^^^^^^^^^^^^^^^^^^
  File "C:\Users\Mihai Telu\AppData\Local\Programs\Python\Python312\Lib\site-packages\django\template\engine.py", line 159, in find_template
    template = loader.get_template(name, skip=skip)
               ^^^^^^^^^^^^^^^^^^^^^^^^^^^^^^^^^^^^
  File "C:\Users\Mihai Telu\AppData\Local\Programs\Python\Python312\Lib\site-packages\django\template\loaders\cached.py", line 57, in get_template
    template = super().get_template(template_name, skip)
               ^^^^^^^^^^^^^^^^^^^^^^^^^^^^^^^^^^^^^^^^^
  File "C:\Users\Mihai Telu\AppData\Local\Programs\Python\Python312\Lib\site-packages\django\template\loaders\base.py", line 28, in get_template
    return Template(
           ^^^^^^^^^
  File "C:\Users\Mihai Telu\AppData\Local\Programs\Python\Python312\Lib\site-packages\django\template\base.py", line 154, in __init__
    self.nodelist = self.compile_nodelist()
                    ^^^^^^^^^^^^^^^^^^^^^^^
  File "C:\Users\Mihai Telu\AppData\Local\Programs\Python\Python312\Lib\site-packages\django\template\base.py", line 196, in compile_nodelist
    nodelist = parser.parse()
               ^^^^^^^^^^^^^^
  File "C:\Users\Mihai Telu\AppData\Local\Programs\Python\Python312\Lib\site-packages\django\template\base.py", line 512, in parse
    self.invalid_block_tag(token, command, parse_until)
  File "C:\Users\Mihai Telu\AppData\Local\Programs\Python\Python312\Lib\site-packages\django\template\base.py", line 573, in invalid_block_tag
    raise self.error(
django.template.exceptions.TemplateSyntaxError: Invalid block tag on line 29: 'endif'. Did you forget to register or load this tag?
ERROR 2025-01-07 14:28:37,700 basehttp "GET /aplicatie/meniu/ HTTP/1.1" 500 145880
ERROR 2025-01-07 14:29:44,818 log Internal Server Error: /aplicatie/meniu/
Traceback (most recent call last):
  File "C:\Users\Mihai Telu\AppData\Local\Programs\Python\Python312\Lib\site-packages\django\template\base.py", line 510, in parse
    compile_func = self.tags[command]
                   ~~~~~~~~~^^^^^^^^^
KeyError: 'endif'

During handling of the above exception, another exception occurred:

Traceback (most recent call last):
  File "C:\Users\Mihai Telu\AppData\Local\Programs\Python\Python312\Lib\site-packages\django\core\handlers\exception.py", line 55, in inner
    response = get_response(request)
               ^^^^^^^^^^^^^^^^^^^^^
  File "C:\Users\Mihai Telu\AppData\Local\Programs\Python\Python312\Lib\site-packages\django\core\handlers\base.py", line 197, in _get_response
    response = wrapped_callback(request, *callback_args, **callback_kwargs)
               ^^^^^^^^^^^^^^^^^^^^^^^^^^^^^^^^^^^^^^^^^^^^^^^^^^^^^^^^^^^^
  File "C:\Users\Mihai Telu\Django\Proiectul_meu\aplicatie\views.py", line 644, in meniu
    return render(request, 'meniu.html',{'ok':ok})
           ^^^^^^^^^^^^^^^^^^^^^^^^^^^^^^^^^^^^^^^
  File "C:\Users\Mihai Telu\AppData\Local\Programs\Python\Python312\Lib\site-packages\django\shortcuts.py", line 25, in render
    content = loader.render_to_string(template_name, context, request, using=using)
              ^^^^^^^^^^^^^^^^^^^^^^^^^^^^^^^^^^^^^^^^^^^^^^^^^^^^^^^^^^^^^^^^^^^^^
  File "C:\Users\Mihai Telu\AppData\Local\Programs\Python\Python312\Lib\site-packages\django\template\loader.py", line 61, in render_to_string
    template = get_template(template_name, using=using)
               ^^^^^^^^^^^^^^^^^^^^^^^^^^^^^^^^^^^^^^^^
  File "C:\Users\Mihai Telu\AppData\Local\Programs\Python\Python312\Lib\site-packages\django\template\loader.py", line 15, in get_template
    return engine.get_template(template_name)
           ^^^^^^^^^^^^^^^^^^^^^^^^^^^^^^^^^^
  File "C:\Users\Mihai Telu\AppData\Local\Programs\Python\Python312\Lib\site-packages\django\template\backends\django.py", line 79, in get_template
    return Template(self.engine.get_template(template_name), self)
                    ^^^^^^^^^^^^^^^^^^^^^^^^^^^^^^^^^^^^^^^
  File "C:\Users\Mihai Telu\AppData\Local\Programs\Python\Python312\Lib\site-packages\django\template\engine.py", line 177, in get_template
    template, origin = self.find_template(template_name)
                       ^^^^^^^^^^^^^^^^^^^^^^^^^^^^^^^^^
  File "C:\Users\Mihai Telu\AppData\Local\Programs\Python\Python312\Lib\site-packages\django\template\engine.py", line 159, in find_template
    template = loader.get_template(name, skip=skip)
               ^^^^^^^^^^^^^^^^^^^^^^^^^^^^^^^^^^^^
  File "C:\Users\Mihai Telu\AppData\Local\Programs\Python\Python312\Lib\site-packages\django\template\loaders\cached.py", line 57, in get_template
    template = super().get_template(template_name, skip)
               ^^^^^^^^^^^^^^^^^^^^^^^^^^^^^^^^^^^^^^^^^
  File "C:\Users\Mihai Telu\AppData\Local\Programs\Python\Python312\Lib\site-packages\django\template\loaders\base.py", line 28, in get_template
    return Template(
           ^^^^^^^^^
  File "C:\Users\Mihai Telu\AppData\Local\Programs\Python\Python312\Lib\site-packages\django\template\base.py", line 154, in __init__
    self.nodelist = self.compile_nodelist()
                    ^^^^^^^^^^^^^^^^^^^^^^^
  File "C:\Users\Mihai Telu\AppData\Local\Programs\Python\Python312\Lib\site-packages\django\template\base.py", line 196, in compile_nodelist
    nodelist = parser.parse()
               ^^^^^^^^^^^^^^
  File "C:\Users\Mihai Telu\AppData\Local\Programs\Python\Python312\Lib\site-packages\django\template\base.py", line 512, in parse
    self.invalid_block_tag(token, command, parse_until)
  File "C:\Users\Mihai Telu\AppData\Local\Programs\Python\Python312\Lib\site-packages\django\template\base.py", line 573, in invalid_block_tag
    raise self.error(
django.template.exceptions.TemplateSyntaxError: Invalid block tag on line 29: 'endif'. Did you forget to register or load this tag?
ERROR 2025-01-07 14:29:44,830 basehttp "GET /aplicatie/meniu/ HTTP/1.1" 500 144824
ERROR 2025-01-07 14:30:59,846 log Internal Server Error: /aplicatie/meniu/
Traceback (most recent call last):
  File "C:\Users\Mihai Telu\AppData\Local\Programs\Python\Python312\Lib\site-packages\django\template\smartif.py", line 180, in translate_token
    op = OPERATORS[token]
         ~~~~~~~~~^^^^^^^
KeyError: 'ok=1'

During handling of the above exception, another exception occurred:

Traceback (most recent call last):
  File "C:\Users\Mihai Telu\AppData\Local\Programs\Python\Python312\Lib\site-packages\django\core\handlers\exception.py", line 55, in inner
    response = get_response(request)
               ^^^^^^^^^^^^^^^^^^^^^
  File "C:\Users\Mihai Telu\AppData\Local\Programs\Python\Python312\Lib\site-packages\django\core\handlers\base.py", line 197, in _get_response
    response = wrapped_callback(request, *callback_args, **callback_kwargs)
               ^^^^^^^^^^^^^^^^^^^^^^^^^^^^^^^^^^^^^^^^^^^^^^^^^^^^^^^^^^^^
  File "C:\Users\Mihai Telu\Django\Proiectul_meu\aplicatie\views.py", line 644, in meniu
    return render(request, 'meniu.html',{'ok':ok})
           ^^^^^^^^^^^^^^^^^^^^^^^^^^^^^^^^^^^^^^^
  File "C:\Users\Mihai Telu\AppData\Local\Programs\Python\Python312\Lib\site-packages\django\shortcuts.py", line 25, in render
    content = loader.render_to_string(template_name, context, request, using=using)
              ^^^^^^^^^^^^^^^^^^^^^^^^^^^^^^^^^^^^^^^^^^^^^^^^^^^^^^^^^^^^^^^^^^^^^
  File "C:\Users\Mihai Telu\AppData\Local\Programs\Python\Python312\Lib\site-packages\django\template\loader.py", line 61, in render_to_string
    template = get_template(template_name, using=using)
               ^^^^^^^^^^^^^^^^^^^^^^^^^^^^^^^^^^^^^^^^
  File "C:\Users\Mihai Telu\AppData\Local\Programs\Python\Python312\Lib\site-packages\django\template\loader.py", line 15, in get_template
    return engine.get_template(template_name)
           ^^^^^^^^^^^^^^^^^^^^^^^^^^^^^^^^^^
  File "C:\Users\Mihai Telu\AppData\Local\Programs\Python\Python312\Lib\site-packages\django\template\backends\django.py", line 79, in get_template
    return Template(self.engine.get_template(template_name), self)
                    ^^^^^^^^^^^^^^^^^^^^^^^^^^^^^^^^^^^^^^^
  File "C:\Users\Mihai Telu\AppData\Local\Programs\Python\Python312\Lib\site-packages\django\template\engine.py", line 177, in get_template
    template, origin = self.find_template(template_name)
                       ^^^^^^^^^^^^^^^^^^^^^^^^^^^^^^^^^
  File "C:\Users\Mihai Telu\AppData\Local\Programs\Python\Python312\Lib\site-packages\django\template\engine.py", line 159, in find_template
    template = loader.get_template(name, skip=skip)
               ^^^^^^^^^^^^^^^^^^^^^^^^^^^^^^^^^^^^
  File "C:\Users\Mihai Telu\AppData\Local\Programs\Python\Python312\Lib\site-packages\django\template\loaders\cached.py", line 57, in get_template
    template = super().get_template(template_name, skip)
               ^^^^^^^^^^^^^^^^^^^^^^^^^^^^^^^^^^^^^^^^^
  File "C:\Users\Mihai Telu\AppData\Local\Programs\Python\Python312\Lib\site-packages\django\template\loaders\base.py", line 28, in get_template
    return Template(
           ^^^^^^^^^
  File "C:\Users\Mihai Telu\AppData\Local\Programs\Python\Python312\Lib\site-packages\django\template\base.py", line 154, in __init__
    self.nodelist = self.compile_nodelist()
                    ^^^^^^^^^^^^^^^^^^^^^^^
  File "C:\Users\Mihai Telu\AppData\Local\Programs\Python\Python312\Lib\site-packages\django\template\base.py", line 196, in compile_nodelist
    nodelist = parser.parse()
               ^^^^^^^^^^^^^^
  File "C:\Users\Mihai Telu\AppData\Local\Programs\Python\Python312\Lib\site-packages\django\template\base.py", line 518, in parse
    raise self.error(token, e)
  File "C:\Users\Mihai Telu\AppData\Local\Programs\Python\Python312\Lib\site-packages\django\template\base.py", line 516, in parse
    compiled_result = compile_func(self, token)
                      ^^^^^^^^^^^^^^^^^^^^^^^^^
  File "C:\Users\Mihai Telu\AppData\Local\Programs\Python\Python312\Lib\site-packages\django\template\defaulttags.py", line 961, in do_if
    condition = TemplateIfParser(parser, bits).parse()
                ^^^^^^^^^^^^^^^^^^^^^^^^^^^^^^
  File "C:\Users\Mihai Telu\AppData\Local\Programs\Python\Python312\Lib\site-packages\django\template\defaulttags.py", line 894, in __init__
    super().__init__(*args, **kwargs)
  File "C:\Users\Mihai Telu\AppData\Local\Programs\Python\Python312\Lib\site-packages\django\template\smartif.py", line 171, in __init__
    mapped_tokens.append(self.translate_token(token))
                         ^^^^^^^^^^^^^^^^^^^^^^^^^^^
  File "C:\Users\Mihai Telu\AppData\Local\Programs\Python\Python312\Lib\site-packages\django\template\smartif.py", line 182, in translate_token
    return self.create_var(token)
           ^^^^^^^^^^^^^^^^^^^^^^
  File "C:\Users\Mihai Telu\AppData\Local\Programs\Python\Python312\Lib\site-packages\django\template\defaulttags.py", line 897, in create_var
    return TemplateLiteral(self.template_parser.compile_filter(value), value)
                           ^^^^^^^^^^^^^^^^^^^^^^^^^^^^^^^^^^^^^^^^^^
  File "C:\Users\Mihai Telu\AppData\Local\Programs\Python\Python312\Lib\site-packages\django\template\base.py", line 605, in compile_filter
    return FilterExpression(token, self)
           ^^^^^^^^^^^^^^^^^^^^^^^^^^^^^
  File "C:\Users\Mihai Telu\AppData\Local\Programs\Python\Python312\Lib\site-packages\django\template\base.py", line 706, in __init__
    raise TemplateSyntaxError(
django.template.exceptions.TemplateSyntaxError: Could not parse the remainder: '=1' from 'ok=1'
ERROR 2025-01-07 14:30:59,865 basehttp "GET /aplicatie/meniu/ HTTP/1.1" 500 176286
ERROR 2025-01-07 14:31:17,706 log Internal Server Error: /aplicatie/meniu/
Traceback (most recent call last):
  File "C:\Users\Mihai Telu\AppData\Local\Programs\Python\Python312\Lib\site-packages\django\template\smartif.py", line 180, in translate_token
    op = OPERATORS[token]
         ~~~~~~~~~^^^^^^^
KeyError: 'ok==1'

During handling of the above exception, another exception occurred:

Traceback (most recent call last):
  File "C:\Users\Mihai Telu\AppData\Local\Programs\Python\Python312\Lib\site-packages\django\core\handlers\exception.py", line 55, in inner
    response = get_response(request)
               ^^^^^^^^^^^^^^^^^^^^^
  File "C:\Users\Mihai Telu\AppData\Local\Programs\Python\Python312\Lib\site-packages\django\core\handlers\base.py", line 197, in _get_response
    response = wrapped_callback(request, *callback_args, **callback_kwargs)
               ^^^^^^^^^^^^^^^^^^^^^^^^^^^^^^^^^^^^^^^^^^^^^^^^^^^^^^^^^^^^
  File "C:\Users\Mihai Telu\Django\Proiectul_meu\aplicatie\views.py", line 644, in meniu
    return render(request, 'meniu.html',{'ok':ok})
           ^^^^^^^^^^^^^^^^^^^^^^^^^^^^^^^^^^^^^^^
  File "C:\Users\Mihai Telu\AppData\Local\Programs\Python\Python312\Lib\site-packages\django\shortcuts.py", line 25, in render
    content = loader.render_to_string(template_name, context, request, using=using)
              ^^^^^^^^^^^^^^^^^^^^^^^^^^^^^^^^^^^^^^^^^^^^^^^^^^^^^^^^^^^^^^^^^^^^^
  File "C:\Users\Mihai Telu\AppData\Local\Programs\Python\Python312\Lib\site-packages\django\template\loader.py", line 61, in render_to_string
    template = get_template(template_name, using=using)
               ^^^^^^^^^^^^^^^^^^^^^^^^^^^^^^^^^^^^^^^^
  File "C:\Users\Mihai Telu\AppData\Local\Programs\Python\Python312\Lib\site-packages\django\template\loader.py", line 15, in get_template
    return engine.get_template(template_name)
           ^^^^^^^^^^^^^^^^^^^^^^^^^^^^^^^^^^
  File "C:\Users\Mihai Telu\AppData\Local\Programs\Python\Python312\Lib\site-packages\django\template\backends\django.py", line 79, in get_template
    return Template(self.engine.get_template(template_name), self)
                    ^^^^^^^^^^^^^^^^^^^^^^^^^^^^^^^^^^^^^^^
  File "C:\Users\Mihai Telu\AppData\Local\Programs\Python\Python312\Lib\site-packages\django\template\engine.py", line 177, in get_template
    template, origin = self.find_template(template_name)
                       ^^^^^^^^^^^^^^^^^^^^^^^^^^^^^^^^^
  File "C:\Users\Mihai Telu\AppData\Local\Programs\Python\Python312\Lib\site-packages\django\template\engine.py", line 159, in find_template
    template = loader.get_template(name, skip=skip)
               ^^^^^^^^^^^^^^^^^^^^^^^^^^^^^^^^^^^^
  File "C:\Users\Mihai Telu\AppData\Local\Programs\Python\Python312\Lib\site-packages\django\template\loaders\cached.py", line 57, in get_template
    template = super().get_template(template_name, skip)
               ^^^^^^^^^^^^^^^^^^^^^^^^^^^^^^^^^^^^^^^^^
  File "C:\Users\Mihai Telu\AppData\Local\Programs\Python\Python312\Lib\site-packages\django\template\loaders\base.py", line 28, in get_template
    return Template(
           ^^^^^^^^^
  File "C:\Users\Mihai Telu\AppData\Local\Programs\Python\Python312\Lib\site-packages\django\template\base.py", line 154, in __init__
    self.nodelist = self.compile_nodelist()
                    ^^^^^^^^^^^^^^^^^^^^^^^
  File "C:\Users\Mihai Telu\AppData\Local\Programs\Python\Python312\Lib\site-packages\django\template\base.py", line 196, in compile_nodelist
    nodelist = parser.parse()
               ^^^^^^^^^^^^^^
  File "C:\Users\Mihai Telu\AppData\Local\Programs\Python\Python312\Lib\site-packages\django\template\base.py", line 518, in parse
    raise self.error(token, e)
  File "C:\Users\Mihai Telu\AppData\Local\Programs\Python\Python312\Lib\site-packages\django\template\base.py", line 516, in parse
    compiled_result = compile_func(self, token)
                      ^^^^^^^^^^^^^^^^^^^^^^^^^
  File "C:\Users\Mihai Telu\AppData\Local\Programs\Python\Python312\Lib\site-packages\django\template\defaulttags.py", line 961, in do_if
    condition = TemplateIfParser(parser, bits).parse()
                ^^^^^^^^^^^^^^^^^^^^^^^^^^^^^^
  File "C:\Users\Mihai Telu\AppData\Local\Programs\Python\Python312\Lib\site-packages\django\template\defaulttags.py", line 894, in __init__
    super().__init__(*args, **kwargs)
  File "C:\Users\Mihai Telu\AppData\Local\Programs\Python\Python312\Lib\site-packages\django\template\smartif.py", line 171, in __init__
    mapped_tokens.append(self.translate_token(token))
                         ^^^^^^^^^^^^^^^^^^^^^^^^^^^
  File "C:\Users\Mihai Telu\AppData\Local\Programs\Python\Python312\Lib\site-packages\django\template\smartif.py", line 182, in translate_token
    return self.create_var(token)
           ^^^^^^^^^^^^^^^^^^^^^^
  File "C:\Users\Mihai Telu\AppData\Local\Programs\Python\Python312\Lib\site-packages\django\template\defaulttags.py", line 897, in create_var
    return TemplateLiteral(self.template_parser.compile_filter(value), value)
                           ^^^^^^^^^^^^^^^^^^^^^^^^^^^^^^^^^^^^^^^^^^
  File "C:\Users\Mihai Telu\AppData\Local\Programs\Python\Python312\Lib\site-packages\django\template\base.py", line 605, in compile_filter
    return FilterExpression(token, self)
           ^^^^^^^^^^^^^^^^^^^^^^^^^^^^^
  File "C:\Users\Mihai Telu\AppData\Local\Programs\Python\Python312\Lib\site-packages\django\template\base.py", line 706, in __init__
    raise TemplateSyntaxError(
django.template.exceptions.TemplateSyntaxError: Could not parse the remainder: '==1' from 'ok==1'
ERROR 2025-01-07 14:31:17,718 basehttp "GET /aplicatie/meniu/ HTTP/1.1" 500 176318
ERROR 2025-01-07 14:32:30,125 log Internal Server Error: /aplicatie/meniu/
Traceback (most recent call last):
  File "C:\Users\Mihai Telu\AppData\Local\Programs\Python\Python312\Lib\site-packages\django\template\smartif.py", line 180, in translate_token
    op = OPERATORS[token]
         ~~~~~~~~~^^^^^^^
KeyError: 'ok!=0'

During handling of the above exception, another exception occurred:

Traceback (most recent call last):
  File "C:\Users\Mihai Telu\AppData\Local\Programs\Python\Python312\Lib\site-packages\django\core\handlers\exception.py", line 55, in inner
    response = get_response(request)
               ^^^^^^^^^^^^^^^^^^^^^
  File "C:\Users\Mihai Telu\AppData\Local\Programs\Python\Python312\Lib\site-packages\django\core\handlers\base.py", line 197, in _get_response
    response = wrapped_callback(request, *callback_args, **callback_kwargs)
               ^^^^^^^^^^^^^^^^^^^^^^^^^^^^^^^^^^^^^^^^^^^^^^^^^^^^^^^^^^^^
  File "C:\Users\Mihai Telu\Django\Proiectul_meu\aplicatie\views.py", line 644, in meniu
    return render(request, 'meniu.html',{'ok':ok})
           ^^^^^^^^^^^^^^^^^^^^^^^^^^^^^^^^^^^^^^^
  File "C:\Users\Mihai Telu\AppData\Local\Programs\Python\Python312\Lib\site-packages\django\shortcuts.py", line 25, in render
    content = loader.render_to_string(template_name, context, request, using=using)
              ^^^^^^^^^^^^^^^^^^^^^^^^^^^^^^^^^^^^^^^^^^^^^^^^^^^^^^^^^^^^^^^^^^^^^
  File "C:\Users\Mihai Telu\AppData\Local\Programs\Python\Python312\Lib\site-packages\django\template\loader.py", line 61, in render_to_string
    template = get_template(template_name, using=using)
               ^^^^^^^^^^^^^^^^^^^^^^^^^^^^^^^^^^^^^^^^
  File "C:\Users\Mihai Telu\AppData\Local\Programs\Python\Python312\Lib\site-packages\django\template\loader.py", line 15, in get_template
    return engine.get_template(template_name)
           ^^^^^^^^^^^^^^^^^^^^^^^^^^^^^^^^^^
  File "C:\Users\Mihai Telu\AppData\Local\Programs\Python\Python312\Lib\site-packages\django\template\backends\django.py", line 79, in get_template
    return Template(self.engine.get_template(template_name), self)
                    ^^^^^^^^^^^^^^^^^^^^^^^^^^^^^^^^^^^^^^^
  File "C:\Users\Mihai Telu\AppData\Local\Programs\Python\Python312\Lib\site-packages\django\template\engine.py", line 177, in get_template
    template, origin = self.find_template(template_name)
                       ^^^^^^^^^^^^^^^^^^^^^^^^^^^^^^^^^
  File "C:\Users\Mihai Telu\AppData\Local\Programs\Python\Python312\Lib\site-packages\django\template\engine.py", line 159, in find_template
    template = loader.get_template(name, skip=skip)
               ^^^^^^^^^^^^^^^^^^^^^^^^^^^^^^^^^^^^
  File "C:\Users\Mihai Telu\AppData\Local\Programs\Python\Python312\Lib\site-packages\django\template\loaders\cached.py", line 57, in get_template
    template = super().get_template(template_name, skip)
               ^^^^^^^^^^^^^^^^^^^^^^^^^^^^^^^^^^^^^^^^^
  File "C:\Users\Mihai Telu\AppData\Local\Programs\Python\Python312\Lib\site-packages\django\template\loaders\base.py", line 28, in get_template
    return Template(
           ^^^^^^^^^
  File "C:\Users\Mihai Telu\AppData\Local\Programs\Python\Python312\Lib\site-packages\django\template\base.py", line 154, in __init__
    self.nodelist = self.compile_nodelist()
                    ^^^^^^^^^^^^^^^^^^^^^^^
  File "C:\Users\Mihai Telu\AppData\Local\Programs\Python\Python312\Lib\site-packages\django\template\base.py", line 196, in compile_nodelist
    nodelist = parser.parse()
               ^^^^^^^^^^^^^^
  File "C:\Users\Mihai Telu\AppData\Local\Programs\Python\Python312\Lib\site-packages\django\template\base.py", line 518, in parse
    raise self.error(token, e)
  File "C:\Users\Mihai Telu\AppData\Local\Programs\Python\Python312\Lib\site-packages\django\template\base.py", line 516, in parse
    compiled_result = compile_func(self, token)
                      ^^^^^^^^^^^^^^^^^^^^^^^^^
  File "C:\Users\Mihai Telu\AppData\Local\Programs\Python\Python312\Lib\site-packages\django\template\defaulttags.py", line 961, in do_if
    condition = TemplateIfParser(parser, bits).parse()
                ^^^^^^^^^^^^^^^^^^^^^^^^^^^^^^
  File "C:\Users\Mihai Telu\AppData\Local\Programs\Python\Python312\Lib\site-packages\django\template\defaulttags.py", line 894, in __init__
    super().__init__(*args, **kwargs)
  File "C:\Users\Mihai Telu\AppData\Local\Programs\Python\Python312\Lib\site-packages\django\template\smartif.py", line 171, in __init__
    mapped_tokens.append(self.translate_token(token))
                         ^^^^^^^^^^^^^^^^^^^^^^^^^^^
  File "C:\Users\Mihai Telu\AppData\Local\Programs\Python\Python312\Lib\site-packages\django\template\smartif.py", line 182, in translate_token
    return self.create_var(token)
           ^^^^^^^^^^^^^^^^^^^^^^
  File "C:\Users\Mihai Telu\AppData\Local\Programs\Python\Python312\Lib\site-packages\django\template\defaulttags.py", line 897, in create_var
    return TemplateLiteral(self.template_parser.compile_filter(value), value)
                           ^^^^^^^^^^^^^^^^^^^^^^^^^^^^^^^^^^^^^^^^^^
  File "C:\Users\Mihai Telu\AppData\Local\Programs\Python\Python312\Lib\site-packages\django\template\base.py", line 605, in compile_filter
    return FilterExpression(token, self)
           ^^^^^^^^^^^^^^^^^^^^^^^^^^^^^
  File "C:\Users\Mihai Telu\AppData\Local\Programs\Python\Python312\Lib\site-packages\django\template\base.py", line 706, in __init__
    raise TemplateSyntaxError(
django.template.exceptions.TemplateSyntaxError: Could not parse the remainder: '!=0' from 'ok!=0'
ERROR 2025-01-07 14:32:30,212 basehttp "GET /aplicatie/meniu/ HTTP/1.1" 500 176322
WARNING 2025-01-07 18:25:17,859 log Forbidden: /aplicatie/adauga_autor/
WARNING 2025-01-07 18:25:17,864 basehttp "GET /aplicatie/adauga_autor/ HTTP/1.1" 403 377
WARNING 2025-01-07 18:27:56,412 log Forbidden: /aplicatie/adauga_autor/
WARNING 2025-01-07 18:27:56,414 basehttp "GET /aplicatie/adauga_autor/ HTTP/1.1" 403 366
WARNING 2025-01-07 18:59:54,635 log Forbidden (CSRF token from POST incorrect.): /aplicatie/login
WARNING 2025-01-07 18:59:54,637 basehttp "POST /aplicatie/login HTTP/1.1" 403 2503
ERROR 2025-01-07 19:05:04,790 log Internal Server Error: /aplicatie/meniu/
Traceback (most recent call last):
  File "C:\Users\Mihai Telu\AppData\Local\Programs\Python\Python312\Lib\site-packages\django\template\base.py", line 510, in parse
    compile_func = self.tags[command]
                   ~~~~~~~~~^^^^^^^^^
KeyError: 'is_administrator_produse'

During handling of the above exception, another exception occurred:

Traceback (most recent call last):
  File "C:\Users\Mihai Telu\AppData\Local\Programs\Python\Python312\Lib\site-packages\django\core\handlers\exception.py", line 55, in inner
    response = get_response(request)
               ^^^^^^^^^^^^^^^^^^^^^
  File "C:\Users\Mihai Telu\AppData\Local\Programs\Python\Python312\Lib\site-packages\django\core\handlers\base.py", line 197, in _get_response
    response = wrapped_callback(request, *callback_args, **callback_kwargs)
               ^^^^^^^^^^^^^^^^^^^^^^^^^^^^^^^^^^^^^^^^^^^^^^^^^^^^^^^^^^^^
  File "C:\Users\Mihai Telu\Django\Proiectul_meu\aplicatie\views.py", line 649, in meniu
    return render(request, 'meniu.html')
           ^^^^^^^^^^^^^^^^^^^^^^^^^^^^^
  File "C:\Users\Mihai Telu\AppData\Local\Programs\Python\Python312\Lib\site-packages\django\shortcuts.py", line 25, in render
    content = loader.render_to_string(template_name, context, request, using=using)
              ^^^^^^^^^^^^^^^^^^^^^^^^^^^^^^^^^^^^^^^^^^^^^^^^^^^^^^^^^^^^^^^^^^^^^
  File "C:\Users\Mihai Telu\AppData\Local\Programs\Python\Python312\Lib\site-packages\django\template\loader.py", line 61, in render_to_string
    template = get_template(template_name, using=using)
               ^^^^^^^^^^^^^^^^^^^^^^^^^^^^^^^^^^^^^^^^
  File "C:\Users\Mihai Telu\AppData\Local\Programs\Python\Python312\Lib\site-packages\django\template\loader.py", line 15, in get_template
    return engine.get_template(template_name)
           ^^^^^^^^^^^^^^^^^^^^^^^^^^^^^^^^^^
  File "C:\Users\Mihai Telu\AppData\Local\Programs\Python\Python312\Lib\site-packages\django\template\backends\django.py", line 79, in get_template
    return Template(self.engine.get_template(template_name), self)
                    ^^^^^^^^^^^^^^^^^^^^^^^^^^^^^^^^^^^^^^^
  File "C:\Users\Mihai Telu\AppData\Local\Programs\Python\Python312\Lib\site-packages\django\template\engine.py", line 177, in get_template
    template, origin = self.find_template(template_name)
                       ^^^^^^^^^^^^^^^^^^^^^^^^^^^^^^^^^
  File "C:\Users\Mihai Telu\AppData\Local\Programs\Python\Python312\Lib\site-packages\django\template\engine.py", line 159, in find_template
    template = loader.get_template(name, skip=skip)
               ^^^^^^^^^^^^^^^^^^^^^^^^^^^^^^^^^^^^
  File "C:\Users\Mihai Telu\AppData\Local\Programs\Python\Python312\Lib\site-packages\django\template\loaders\cached.py", line 57, in get_template
    template = super().get_template(template_name, skip)
               ^^^^^^^^^^^^^^^^^^^^^^^^^^^^^^^^^^^^^^^^^
  File "C:\Users\Mihai Telu\AppData\Local\Programs\Python\Python312\Lib\site-packages\django\template\loaders\base.py", line 28, in get_template
    return Template(
           ^^^^^^^^^
  File "C:\Users\Mihai Telu\AppData\Local\Programs\Python\Python312\Lib\site-packages\django\template\base.py", line 154, in __init__
    self.nodelist = self.compile_nodelist()
                    ^^^^^^^^^^^^^^^^^^^^^^^
  File "C:\Users\Mihai Telu\AppData\Local\Programs\Python\Python312\Lib\site-packages\django\template\base.py", line 196, in compile_nodelist
    nodelist = parser.parse()
               ^^^^^^^^^^^^^^
  File "C:\Users\Mihai Telu\AppData\Local\Programs\Python\Python312\Lib\site-packages\django\template\base.py", line 512, in parse
    self.invalid_block_tag(token, command, parse_until)
  File "C:\Users\Mihai Telu\AppData\Local\Programs\Python\Python312\Lib\site-packages\django\template\base.py", line 573, in invalid_block_tag
    raise self.error(
django.template.exceptions.TemplateSyntaxError: Invalid block tag on line 31: 'is_administrator_produse'. Did you forget to register or load this tag?
ERROR 2025-01-07 19:05:04,809 basehttp "GET /aplicatie/meniu/ HTTP/1.1" 500 144979
ERROR 2025-01-07 19:16:34,345 log Internal Server Error: /aplicatie/meniu/
Traceback (most recent call last):
  File "C:\Users\Mihai Telu\AppData\Local\Programs\Python\Python312\Lib\site-packages\django\core\handlers\exception.py", line 55, in inner
    response = get_response(request)
               ^^^^^^^^^^^^^^^^^^^^^
  File "C:\Users\Mihai Telu\AppData\Local\Programs\Python\Python312\Lib\site-packages\django\core\handlers\base.py", line 197, in _get_response
    response = wrapped_callback(request, *callback_args, **callback_kwargs)
               ^^^^^^^^^^^^^^^^^^^^^^^^^^^^^^^^^^^^^^^^^^^^^^^^^^^^^^^^^^^^
  File "C:\Users\Mihai Telu\Django\Proiectul_meu\aplicatie\views.py", line 650, in meniu
    print(permisiuni.is_administrator_produse)
          ^^^^^^^^^^^^^^^^^^^^^^^^^^^^^^^^^^^
AttributeError: 'dict' object has no attribute 'is_administrator_produse'
ERROR 2025-01-07 19:16:34,349 basehttp "GET /aplicatie/meniu/ HTTP/1.1" 500 68052
ERROR 2025-01-07 19:20:21,829 log Internal Server Error: /aplicatie/meniu/
Traceback (most recent call last):
  File "C:\Users\Mihai Telu\AppData\Local\Programs\Python\Python312\Lib\site-packages\django\template\smartif.py", line 180, in translate_token
    op = OPERATORS[token]
         ~~~~~~~~~^^^^^^^
KeyError: '{{is_administrator_produse}}'

During handling of the above exception, another exception occurred:

Traceback (most recent call last):
  File "C:\Users\Mihai Telu\AppData\Local\Programs\Python\Python312\Lib\site-packages\django\core\handlers\exception.py", line 55, in inner
    response = get_response(request)
               ^^^^^^^^^^^^^^^^^^^^^
  File "C:\Users\Mihai Telu\AppData\Local\Programs\Python\Python312\Lib\site-packages\django\core\handlers\base.py", line 197, in _get_response
    response = wrapped_callback(request, *callback_args, **callback_kwargs)
               ^^^^^^^^^^^^^^^^^^^^^^^^^^^^^^^^^^^^^^^^^^^^^^^^^^^^^^^^^^^^
  File "C:\Users\Mihai Telu\Django\Proiectul_meu\aplicatie\views.py", line 650, in meniu
    return render(request, 'meniu.html', permisiuni)
           ^^^^^^^^^^^^^^^^^^^^^^^^^^^^^^^^^^^^^^^^^
  File "C:\Users\Mihai Telu\AppData\Local\Programs\Python\Python312\Lib\site-packages\django\shortcuts.py", line 25, in render
    content = loader.render_to_string(template_name, context, request, using=using)
              ^^^^^^^^^^^^^^^^^^^^^^^^^^^^^^^^^^^^^^^^^^^^^^^^^^^^^^^^^^^^^^^^^^^^^
  File "C:\Users\Mihai Telu\AppData\Local\Programs\Python\Python312\Lib\site-packages\django\template\loader.py", line 61, in render_to_string
    template = get_template(template_name, using=using)
               ^^^^^^^^^^^^^^^^^^^^^^^^^^^^^^^^^^^^^^^^
  File "C:\Users\Mihai Telu\AppData\Local\Programs\Python\Python312\Lib\site-packages\django\template\loader.py", line 15, in get_template
    return engine.get_template(template_name)
           ^^^^^^^^^^^^^^^^^^^^^^^^^^^^^^^^^^
  File "C:\Users\Mihai Telu\AppData\Local\Programs\Python\Python312\Lib\site-packages\django\template\backends\django.py", line 79, in get_template
    return Template(self.engine.get_template(template_name), self)
                    ^^^^^^^^^^^^^^^^^^^^^^^^^^^^^^^^^^^^^^^
  File "C:\Users\Mihai Telu\AppData\Local\Programs\Python\Python312\Lib\site-packages\django\template\engine.py", line 177, in get_template
    template, origin = self.find_template(template_name)
                       ^^^^^^^^^^^^^^^^^^^^^^^^^^^^^^^^^
  File "C:\Users\Mihai Telu\AppData\Local\Programs\Python\Python312\Lib\site-packages\django\template\engine.py", line 159, in find_template
    template = loader.get_template(name, skip=skip)
               ^^^^^^^^^^^^^^^^^^^^^^^^^^^^^^^^^^^^
  File "C:\Users\Mihai Telu\AppData\Local\Programs\Python\Python312\Lib\site-packages\django\template\loaders\cached.py", line 57, in get_template
    template = super().get_template(template_name, skip)
               ^^^^^^^^^^^^^^^^^^^^^^^^^^^^^^^^^^^^^^^^^
  File "C:\Users\Mihai Telu\AppData\Local\Programs\Python\Python312\Lib\site-packages\django\template\loaders\base.py", line 28, in get_template
    return Template(
           ^^^^^^^^^
  File "C:\Users\Mihai Telu\AppData\Local\Programs\Python\Python312\Lib\site-packages\django\template\base.py", line 154, in __init__
    self.nodelist = self.compile_nodelist()
                    ^^^^^^^^^^^^^^^^^^^^^^^
  File "C:\Users\Mihai Telu\AppData\Local\Programs\Python\Python312\Lib\site-packages\django\template\base.py", line 196, in compile_nodelist
    nodelist = parser.parse()
               ^^^^^^^^^^^^^^
  File "C:\Users\Mihai Telu\AppData\Local\Programs\Python\Python312\Lib\site-packages\django\template\base.py", line 518, in parse
    raise self.error(token, e)
  File "C:\Users\Mihai Telu\AppData\Local\Programs\Python\Python312\Lib\site-packages\django\template\base.py", line 516, in parse
    compiled_result = compile_func(self, token)
                      ^^^^^^^^^^^^^^^^^^^^^^^^^
  File "C:\Users\Mihai Telu\AppData\Local\Programs\Python\Python312\Lib\site-packages\django\template\defaulttags.py", line 961, in do_if
    condition = TemplateIfParser(parser, bits).parse()
                ^^^^^^^^^^^^^^^^^^^^^^^^^^^^^^
  File "C:\Users\Mihai Telu\AppData\Local\Programs\Python\Python312\Lib\site-packages\django\template\defaulttags.py", line 894, in __init__
    super().__init__(*args, **kwargs)
  File "C:\Users\Mihai Telu\AppData\Local\Programs\Python\Python312\Lib\site-packages\django\template\smartif.py", line 171, in __init__
    mapped_tokens.append(self.translate_token(token))
                         ^^^^^^^^^^^^^^^^^^^^^^^^^^^
  File "C:\Users\Mihai Telu\AppData\Local\Programs\Python\Python312\Lib\site-packages\django\template\smartif.py", line 182, in translate_token
    return self.create_var(token)
           ^^^^^^^^^^^^^^^^^^^^^^
  File "C:\Users\Mihai Telu\AppData\Local\Programs\Python\Python312\Lib\site-packages\django\template\defaulttags.py", line 897, in create_var
    return TemplateLiteral(self.template_parser.compile_filter(value), value)
                           ^^^^^^^^^^^^^^^^^^^^^^^^^^^^^^^^^^^^^^^^^^
  File "C:\Users\Mihai Telu\AppData\Local\Programs\Python\Python312\Lib\site-packages\django\template\base.py", line 605, in compile_filter
    return FilterExpression(token, self)
           ^^^^^^^^^^^^^^^^^^^^^^^^^^^^^
  File "C:\Users\Mihai Telu\AppData\Local\Programs\Python\Python312\Lib\site-packages\django\template\base.py", line 706, in __init__
    raise TemplateSyntaxError(
django.template.exceptions.TemplateSyntaxError: Could not parse the remainder: '{{is_administrator_produse}}' from '{{is_administrator_produse}}'
ERROR 2025-01-07 19:20:21,845 basehttp "GET /aplicatie/meniu/ HTTP/1.1" 500 176505
WARNING 2025-01-07 19:34:38,079 log Forbidden (CSRF token from POST incorrect.): /admin/login/
WARNING 2025-01-07 19:34:38,080 basehttp "POST /admin/login/?next=/admin/ HTTP/1.1" 403 2503
WARNING 2025-01-07 19:34:46,190 log Forbidden (CSRF token from POST incorrect.): /admin/login/
WARNING 2025-01-07 19:34:46,191 basehttp "POST /admin/login/?next=/admin/ HTTP/1.1" 403 2503
WARNING 2025-01-07 20:08:38,654 log Forbidden (CSRF token from POST incorrect.): /aplicatie/login
WARNING 2025-01-07 20:08:38,656 basehttp "POST /aplicatie/login HTTP/1.1" 403 2503
WARNING 2025-01-09 16:27:14,218 log Not Found: /aplicatie/adauga_elev
WARNING 2025-01-09 16:27:14,220 basehttp "GET /aplicatie/adauga_elev HTTP/1.1" 404 9674
